Workbook

Sheet result
M1: 第1口 | Z1: 第2口 | AM1: 第3口 | AZ1: 第4口 | BM1: 第5口
A2: 回別 | B2: 抽せん日 | C2: 本数字 | J2: ボーナス数字 | M2: 1 | N2: 2 | O2: 3 | P2: 4 | Q2: 5 | R2: 6 | S2: 7 | T2: B1 | U2: B2 | V2: R | W2: B | X2: T | Z2: 1 | AA2: 2 | AB2: 3 | AC2: 4 | AD2: 5 | AE2: 6 | AF2: 7 | AG2: B1 | AH2: B2 | AI2: R | AJ2: B | AK2: T | AM2: 1 | AN2: 2 | AO2: 3 | AP2: 4 | AQ2: 5 | AR2: 6 | AS2: 7 | AT2: B1 | AU2: B2 | AV2: R | AW2: B | AX2: T | AZ2: 1 | BA2: 2 | BB2: 3 | BC2: 4 | BD2: 5 | BE2: 6 | BF2: 7 | BG2: B1 | BH2: B2 | BI2: R | BJ2: B | BK2: T | BM2: 1 | BN2: 2 | BO2: 3 | BP2: 4 | BQ2: 5 | BR2: 6 | BS2: 7 | BT2: B1 | BU2: B2 | BV2: R | BW2: B | BX2: T
A3: 第1回 | B3: 2013年4月5日 | C3: 07 | D3: 10 | E3: 12 | F3: 17 | G3: 23 | H3: 28 | I3: 34 | J3: 03 | K3: 15 | M3: =COUNTIF(pick!$C$2:$I$2,C3) -> 1 | N3: =COUNTIF(pick!$C$2:$I$2,D3) -> 0 | O3: =COUNTIF(pick!$C$2:$I$2,E3) -> 0 | P3: =COUNTIF(pick!$C$2:$I$2,F3) -> 0 | Q3: =COUNTIF(pick!$C$2:$I$2,G3) -> 0 | R3: =COUNTIF(pick!$C$2:$I$2,H3) -> 0 | S3: =COUNTIF(pick!$C$2:$I$2,I3) -> 0 | T3: =COUNTIF(pick!$C$2:$I$2,J3) -> 1 | U3: =COUNTIF(pick!$C$2:$I$2,K3) -> 0 | V3: =SUM(M3:S3) -> 1 | W3: =SUM(T3:U3) -> 1 | X3: =SUM(M3:U3) -> 2 | Z3: =COUNTIF(pick!$C$3:$I$3,C3) -> 1 | AA3: =COUNTIF(pick!$C$3:$I$3,D3) -> 0 | AB3: =COUNTIF(pick!$C$3:$I$3,E3) -> 0 | AC3: =COUNTIF(pick!$C$3:$I$3,F3) -> 0 | AD3: =COUNTIF(pick!$C$3:$I$3,G3) -> 0 | AE3: =COUNTIF(pick!$C$3:$I$3,H3) -> 0 | AF3: =COUNTIF(pick!$C$3:$I$3,I3) -> 0 | AG3: =COUNTIF(pick!$C$3:$I$3,J3) -> 1 | AH3: =COUNTIF(pick!$C$3:$I$3,K3) -> 0 | AI3: =SUM(Z3:AF3) -> 1 | AJ3: =SUM(AG3:AH3) -> 1 | AK3: =SUM(Z3:AH3) -> 2 | AM3: =COUNTIF(pick!$C$4:$I$4,C3) -> 1 | AN3: =COUNTIF(pick!$C$4:$I$4,D3) -> 0 | AO3: =COUNTIF(pick!$C$4:$I$4,E3) -> 0 | AP3: =COUNTIF(pick!$C$4:$I$4,F3) -> 0 | AQ3: =COUNTIF(pick!$C$4:$I$4,G3) -> 0 | AR3: =COUNTIF(pick!$C$4:$I$4,H3) -> 0 | AS3: =COUNTIF(pick!$C$4:$I$4,I3) -> 0 | AT3: =COUNTIF(pick!$C$4:$I$4,J3) -> 1 | AU3: =COUNTIF(pick!$C$4:$I$4,K3) -> 0 | AV3: =SUM(AM3:AS3) -> 1 | AW3: =SUM(AT3:AU3) -> 1 | AX3: =SUM(AM3:AU3) -> 2 | AZ3: =COUNTIF(pick!$C$5:$I$5,C3) -> 1 | BA3: =COUNTIF(pick!$C$5:$I$5,D3) -> 1 | BB3: =COUNTIF(pick!$C$5:$I$5,E3) -> 0 | BC3: =COUNTIF(pick!$C$5:$I$5,F3) -> 0 | BD3: =COUNTIF(pick!$C$5:$I$5,G3) -> 0 | BE3: =COUNTIF(pick!$C$5:$I$5,H3) -> 0 | BF3: =COUNTIF(pick!$C$5:$I$5,I3) -> 0 | BG3: =COUNTIF(pick!$C$5:$I$5,J3) -> 0 | BH3: =COUNTIF(pick!$C$5:$I$5,K3) -> 0 | BI3: =SUM(AZ3:BF3) -> 2 | BJ3: =SUM(BG3:BH3) -> 0 | BK3: =SUM(AZ3:BH3) -> 2 | BM3: =COUNTIF(pick!$C$6:$I$6,C3) -> 1 | BN3: =COUNTIF(pick!$C$6:$I$6,D3) -> 1 | BO3: =COUNTIF(pick!$C$6:$I$6,E3) -> 0 | BP3: =COUNTIF(pick!$C$6:$I$6,F3) -> 0 | BQ3: =COUNTIF(pick!$C$6:$I$6,G3) -> 0 | BR3: =COUNTIF(pick!$C$6:$I$6,H3) -> 0 | BS3: =COUNTIF(pick!$C$6:$I$6,I3) -> 0 | BT3: =COUNTIF(pick!$C$6:$I$6,J3) -> 0 | BU3: =COUNTIF(pick!$C$6:$I$6,K3) -> 0 | BV3: =SUM(BM3:BS3) -> 2 | BW3: =SUM(BT3:BU3) -> 0 | BX3: =SUM(BM3:BU3) -> 2
A4: 第2回 | B4: 2013年4月12日 | C4: 20 | D4: 24 | E4: 29 | F4: 31 | G4: 33 | H4: 34 | I4: 35 | J4: 12 | K4: 32 | M4: =COUNTIF(pick!$C$2:$I$2,C4) -> 0 | N4: =COUNTIF(pick!$C$2:$I$2,D4) -> 0 | O4: =COUNTIF(pick!$C$2:$I$2,E4) -> 0 | P4: =COUNTIF(pick!$C$2:$I$2,F4) -> 0 | Q4: =COUNTIF(pick!$C$2:$I$2,G4) -> 0 | R4: =COUNTIF(pick!$C$2:$I$2,H4) -> 0 | S4: =COUNTIF(pick!$C$2:$I$2,I4) -> 0 | T4: =COUNTIF(pick!$C$2:$I$2,J4) -> 0 | U4: =COUNTIF(pick!$C$2:$I$2,K4) -> 0 | V4: =SUM(M4:S4) -> 0 | W4: =SUM(T4:U4) -> 0 | X4: =SUM(M4:U4) -> 0 | Z4: =COUNTIF(pick!$C$3:$I$3,C4) -> 0 | AA4: =COUNTIF(pick!$C$3:$I$3,D4) -> 0 | AB4: =COUNTIF(pick!$C$3:$I$3,E4) -> 0 | AC4: =COUNTIF(pick!$C$3:$I$3,F4) -> 0 | AD4: =COUNTIF(pick!$C$3:$I$3,G4) -> 0 | AE4: =COUNTIF(pick!$C$3:$I$3,H4) -> 0 | AF4: =COUNTIF(pick!$C$3:$I$3,I4) -> 0 | AG4: =COUNTIF(pick!$C$3:$I$3,J4) -> 0 | AH4: =COUNTIF(pick!$C$3:$I$3,K4) -> 0 | AI4: =SUM(Z4:AF4) -> 0 | AJ4: =SUM(AG4:AH4) -> 0 | AK4: =SUM(Z4:AH4) -> 0 | AM4: =COUNTIF(pick!$C$4:$I$4,C4) -> 0 | AN4: =COUNTIF(pick!$C$4:$I$4,D4) -> 0 | AO4: =COUNTIF(pick!$C$4:$I$4,E4) -> 0 | AP4: =COUNTIF(pick!$C$4:$I$4,F4) -> 0 | AQ4: =COUNTIF(pick!$C$4:$I$4,G4) -> 0 | AR4: =COUNTIF(pick!$C$4:$I$4,H4) -> 0 | AS4: =COUNTIF(pick!$C$4:$I$4,I4) -> 0 | AT4: =COUNTIF(pick!$C$4:$I$4,J4) -> 0 | AU4: =COUNTIF(pick!$C$4:$I$4,K4) -> 0 | AV4: =SUM(AM4:AS4) -> 0 | AW4: =SUM(AT4:AU4) -> 0 | AX4: =SUM(AM4:AU4) -> 0 | AZ4: =COUNTIF(pick!$C$5:$I$5,C4) -> 0 | BA4: =COUNTIF(pick!$C$5:$I$5,D4) -> 0 | BB4: =COUNTIF(pick!$C$5:$I$5,E4) -> 0 | BC4: =COUNTIF(pick!$C$5:$I$5,F4) -> 0 | BD4: =COUNTIF(pick!$C$5:$I$5,G4) -> 0 | BE4: =COUNTIF(pick!$C$5:$I$5,H4) -> 0 | BF4: =COUNTIF(pick!$C$5:$I$5,I4) -> 0 | BG4: =COUNTIF(pick!$C$5:$I$5,J4) -> 0 | BH4: =COUNTIF(pick!$C$5:$I$5,K4) -> 0 | BI4: =SUM(AZ4:BF4) -> 0 | BJ4: =SUM(BG4:BH4) -> 0 | BK4: =SUM(AZ4:BH4) -> 0 | BM4: =COUNTIF(pick!$C$6:$I$6,C4) -> 0 | BN4: =COUNTIF(pick!$C$6:$I$6,D4) -> 0 | BO4: =COUNTIF(pick!$C$6:$I$6,E4) -> 0 | BP4: =COUNTIF(pick!$C$6:$I$6,F4) -> 0 | BQ4: =COUNTIF(pick!$C$6:$I$6,G4) -> 0 | BR4: =COUNTIF(pick!$C$6:$I$6,H4) -> 0 | BS4: =COUNTIF(pick!$C$6:$I$6,I4) -> 0 | BT4: =COUNTIF(pick!$C$6:$I$6,J4) -> 0 | BU4: =COUNTIF(pick!$C$6:$I$6,K4) -> 0 | BV4: =SUM(BM4:BS4) -> 0 | BW4: =SUM(BT4:BU4) -> 0 | BX4: =SUM(BM4:BU4) -> 0
A5: 第3回 | B5: 2013年4月19日 | C5: 02 | D5: 07 | E5: 08 | F5: 11 | G5: 14 | H5: 23 | I5: 31 | J5: 05 | K5: 15 | M5: =COUNTIF(pick!$C$2:$I$2,C5) -> 1 | N5: =COUNTIF(pick!$C$2:$I$2,D5) -> 1 | O5: =COUNTIF(pick!$C$2:$I$2,E5) -> 0 | P5: =COUNTIF(pick!$C$2:$I$2,F5) -> 0 | Q5: =COUNTIF(pick!$C$2:$I$2,G5) -> 0 | R5: =COUNTIF(pick!$C$2:$I$2,H5) -> 0 | S5: =COUNTIF(pick!$C$2:$I$2,I5) -> 0 | T5: =COUNTIF(pick!$C$2:$I$2,J5) -> 1 | U5: =COUNTIF(pick!$C$2:$I$2,K5) -> 0 | V5: =SUM(M5:S5) -> 2 | W5: =SUM(T5:U5) -> 1 | X5: =SUM(M5:U5) -> 3 | Z5: =COUNTIF(pick!$C$3:$I$3,C5) -> 1 | AA5: =COUNTIF(pick!$C$3:$I$3,D5) -> 1 | AB5: =COUNTIF(pick!$C$3:$I$3,E5) -> 1 | AC5: =COUNTIF(pick!$C$3:$I$3,F5) -> 0 | AD5: =COUNTIF(pick!$C$3:$I$3,G5) -> 0 | AE5: =COUNTIF(pick!$C$3:$I$3,H5) -> 0 | AF5: =COUNTIF(pick!$C$3:$I$3,I5) -> 0 | AG5: =COUNTIF(pick!$C$3:$I$3,J5) -> 1 | AH5: =COUNTIF(pick!$C$3:$I$3,K5) -> 0 | AI5: =SUM(Z5:AF5) -> 3 | AJ5: =SUM(AG5:AH5) -> 1 | AK5: =SUM(Z5:AH5) -> 4 | AM5: =COUNTIF(pick!$C$4:$I$4,C5) -> 0 | AN5: =COUNTIF(pick!$C$4:$I$4,D5) -> 1 | AO5: =COUNTIF(pick!$C$4:$I$4,E5) -> 1 | AP5: =COUNTIF(pick!$C$4:$I$4,F5) -> 0 | AQ5: =COUNTIF(pick!$C$4:$I$4,G5) -> 0 | AR5: =COUNTIF(pick!$C$4:$I$4,H5) -> 0 | AS5: =COUNTIF(pick!$C$4:$I$4,I5) -> 0 | AT5: =COUNTIF(pick!$C$4:$I$4,J5) -> 1 | AU5: =COUNTIF(pick!$C$4:$I$4,K5) -> 0 | AV5: =SUM(AM5:AS5) -> 2 | AW5: =SUM(AT5:AU5) -> 1 | AX5: =SUM(AM5:AU5) -> 3 | AZ5: =COUNTIF(pick!$C$5:$I$5,C5) -> 0 | BA5: =COUNTIF(pick!$C$5:$I$5,D5) -> 1 | BB5: =COUNTIF(pick!$C$5:$I$5,E5) -> 1 | BC5: =COUNTIF(pick!$C$5:$I$5,F5) -> 0 | BD5: =COUNTIF(pick!$C$5:$I$5,G5) -> 0 | BE5: =COUNTIF(pick!$C$5:$I$5,H5) -> 0 | BF5: =COUNTIF(pick!$C$5:$I$5,I5) -> 0 | BG5: =COUNTIF(pick!$C$5:$I$5,J5) -> 1 | BH5: =COUNTIF(pick!$C$5:$I$5,K5) -> 0 | BI5: =SUM(AZ5:BF5) -> 2 | BJ5: =SUM(BG5:BH5) -> 1 | BK5: =SUM(AZ5:BH5) -> 3 | BM5: =COUNTIF(pick!$C$6:$I$6,C5) -> 0 | BN5: =COUNTIF(pick!$C$6:$I$6,D5) -> 1 | BO5: =COUNTIF(pick!$C$6:$I$6,E5) -> 1 | BP5: =COUNTIF(pick!$C$6:$I$6,F5) -> 1 | BQ5: =COUNTIF(pick!$C$6:$I$6,G5) -> 0 | BR5: =COUNTIF(pick!$C$6:$I$6,H5) -> 0 | BS5: =COUNTIF(pick!$C$6:$I$6,I5) -> 0 | BT5: =COUNTIF(pick!$C$6:$I$6,J5) -> 1 | BU5: =COUNTIF(pick!$C$6:$I$6,K5) -> 0 | BV5: =SUM(BM5:BS5) -> 3 | BW5: =SUM(BT5:BU5) -> 1 | BX5: =SUM(BM5:BU5) -> 4
A6: 第4回 | B6: 2013年4月26日 | C6: 12 | D6: 13 | E6: 22 | F6: 23 | G6: 24 | H6: 28 | I6: 29 | J6: 02 | K6: 14 | M6: =COUNTIF(pick!$C$2:$I$2,C6) -> 0 | N6: =COUNTIF(pick!$C$2:$I$2,D6) -> 0 | O6: =COUNTIF(pick!$C$2:$I$2,E6) -> 0 | P6: =COUNTIF(pick!$C$2:$I$2,F6) -> 0 | Q6: =COUNTIF(pick!$C$2:$I$2,G6) -> 0 | R6: =COUNTIF(pick!$C$2:$I$2,H6) -> 0 | S6: =COUNTIF(pick!$C$2:$I$2,I6) -> 0 | T6: =COUNTIF(pick!$C$2:$I$2,J6) -> 1 | U6: =COUNTIF(pick!$C$2:$I$2,K6) -> 0 | V6: =SUM(M6:S6) -> 0 | W6: =SUM(T6:U6) -> 1 | X6: =SUM(M6:U6) -> 1 | Z6: =COUNTIF(pick!$C$3:$I$3,C6) -> 0 | AA6: =COUNTIF(pick!$C$3:$I$3,D6) -> 0 | AB6: =COUNTIF(pick!$C$3:$I$3,E6) -> 0 | AC6: =COUNTIF(pick!$C$3:$I$3,F6) -> 0 | AD6: =COUNTIF(pick!$C$3:$I$3,G6) -> 0 | AE6: =COUNTIF(pick!$C$3:$I$3,H6) -> 0 | AF6: =COUNTIF(pick!$C$3:$I$3,I6) -> 0 | AG6: =COUNTIF(pick!$C$3:$I$3,J6) -> 1 | AH6: =COUNTIF(pick!$C$3:$I$3,K6) -> 0 | AI6: =SUM(Z6:AF6) -> 0 | AJ6: =SUM(AG6:AH6) -> 1 | AK6: =SUM(Z6:AH6) -> 1 | AM6: =COUNTIF(pick!$C$4:$I$4,C6) -> 0 | AN6: =COUNTIF(pick!$C$4:$I$4,D6) -> 0 | AO6: =COUNTIF(pick!$C$4:$I$4,E6) -> 0 | AP6: =COUNTIF(pick!$C$4:$I$4,F6) -> 0 | AQ6: =COUNTIF(pick!$C$4:$I$4,G6) -> 0 | AR6: =COUNTIF(pick!$C$4:$I$4,H6) -> 0 | AS6: =COUNTIF(pick!$C$4:$I$4,I6) -> 0 | AT6: =COUNTIF(pick!$C$4:$I$4,J6) -> 0 | AU6: =COUNTIF(pick!$C$4:$I$4,K6) -> 0 | AV6: =SUM(AM6:AS6) -> 0 | AW6: =SUM(AT6:AU6) -> 0 | AX6: =SUM(AM6:AU6) -> 0 | AZ6: =COUNTIF(pick!$C$5:$I$5,C6) -> 0 | BA6: =COUNTIF(pick!$C$5:$I$5,D6) -> 0 | BB6: =COUNTIF(pick!$C$5:$I$5,E6) -> 0 | BC6: =COUNTIF(pick!$C$5:$I$5,F6) -> 0 | BD6: =COUNTIF(pick!$C$5:$I$5,G6) -> 0 | BE6: =COUNTIF(pick!$C$5:$I$5,H6) -> 0 | BF6: =COUNTIF(pick!$C$5:$I$5,I6) -> 0 | BG6: =COUNTIF(pick!$C$5:$I$5,J6) -> 0 | BH6: =COUNTIF(pick!$C$5:$I$5,K6) -> 0 | BI6: =SUM(AZ6:BF6) -> 0 | BJ6: =SUM(BG6:BH6) -> 0 | BK6: =SUM(AZ6:BH6) -> 0 | BM6: =COUNTIF(pick!$C$6:$I$6,C6) -> 0 | BN6: =COUNTIF(pick!$C$6:$I$6,D6) -> 0 | BO6: =COUNTIF(pick!$C$6:$I$6,E6) -> 0 | BP6: =COUNTIF(pick!$C$6:$I$6,F6) -> 0 | BQ6: =COUNTIF(pick!$C$6:$I$6,G6) -> 0 | BR6: =COUNTIF(pick!$C$6:$I$6,H6) -> 0 | BS6: =COUNTIF(pick!$C$6:$I$6,I6) -> 0 | BT6: =COUNTIF(pick!$C$6:$I$6,J6) -> 0 | BU6: =COUNTIF(pick!$C$6:$I$6,K6) -> 0 | BV6: =SUM(BM6:BS6) -> 0 | BW6: =SUM(BT6:BU6) -> 0 | BX6: =SUM(BM6:BU6) -> 0
A7: 第5回 | B7: 2013年5月3日 | C7: 01 | D7: 03 | E7: 04 | F7: 05 | G7: 16 | H7: 21 | I7: 28 | J7: 22 | K7: 31 | M7: =COUNTIF(pick!$C$2:$I$2,C7) -> 1 | N7: =COUNTIF(pick!$C$2:$I$2,D7) -> 1 | O7: =COUNTIF(pick!$C$2:$I$2,E7) -> 1 | P7: =COUNTIF(pick!$C$2:$I$2,F7) -> 1 | Q7: =COUNTIF(pick!$C$2:$I$2,G7) -> 0 | R7: =COUNTIF(pick!$C$2:$I$2,H7) -> 0 | S7: =COUNTIF(pick!$C$2:$I$2,I7) -> 0 | T7: =COUNTIF(pick!$C$2:$I$2,J7) -> 0 | U7: =COUNTIF(pick!$C$2:$I$2,K7) -> 0 | V7: =SUM(M7:S7) -> 4 | W7: =SUM(T7:U7) -> 0 | X7: =SUM(M7:U7) -> 4 | Z7: =COUNTIF(pick!$C$3:$I$3,C7) -> 0 | AA7: =COUNTIF(pick!$C$3:$I$3,D7) -> 1 | AB7: =COUNTIF(pick!$C$3:$I$3,E7) -> 1 | AC7: =COUNTIF(pick!$C$3:$I$3,F7) -> 1 | AD7: =COUNTIF(pick!$C$3:$I$3,G7) -> 0 | AE7: =COUNTIF(pick!$C$3:$I$3,H7) -> 0 | AF7: =COUNTIF(pick!$C$3:$I$3,I7) -> 0 | AG7: =COUNTIF(pick!$C$3:$I$3,J7) -> 0 | AH7: =COUNTIF(pick!$C$3:$I$3,K7) -> 0 | AI7: =SUM(Z7:AF7) -> 3 | AJ7: =SUM(AG7:AH7) -> 0 | AK7: =SUM(Z7:AH7) -> 3 | AM7: =COUNTIF(pick!$C$4:$I$4,C7) -> 0 | AN7: =COUNTIF(pick!$C$4:$I$4,D7) -> 1 | AO7: =COUNTIF(pick!$C$4:$I$4,E7) -> 1 | AP7: =COUNTIF(pick!$C$4:$I$4,F7) -> 1 | AQ7: =COUNTIF(pick!$C$4:$I$4,G7) -> 0 | AR7: =COUNTIF(pick!$C$4:$I$4,H7) -> 0 | AS7: =COUNTIF(pick!$C$4:$I$4,I7) -> 0 | AT7: =COUNTIF(pick!$C$4:$I$4,J7) -> 0 | AU7: =COUNTIF(pick!$C$4:$I$4,K7) -> 0 | AV7: =SUM(AM7:AS7) -> 3 | AW7: =SUM(AT7:AU7) -> 0 | AX7: =SUM(AM7:AU7) -> 3 | AZ7: =COUNTIF(pick!$C$5:$I$5,C7) -> 0 | BA7: =COUNTIF(pick!$C$5:$I$5,D7) -> 0 | BB7: =COUNTIF(pick!$C$5:$I$5,E7) -> 1 | BC7: =COUNTIF(pick!$C$5:$I$5,F7) -> 1 | BD7: =COUNTIF(pick!$C$5:$I$5,G7) -> 0 | BE7: =COUNTIF(pick!$C$5:$I$5,H7) -> 0 | BF7: =COUNTIF(pick!$C$5:$I$5,I7) -> 0 | BG7: =COUNTIF(pick!$C$5:$I$5,J7) -> 0 | BH7: =COUNTIF(pick!$C$5:$I$5,K7) -> 0 | BI7: =SUM(AZ7:BF7) -> 2 | BJ7: =SUM(BG7:BH7) -> 0 | BK7: =SUM(AZ7:BH7) -> 2 | BM7: =COUNTIF(pick!$C$6:$I$6,C7) -> 0 | BN7: =COUNTIF(pick!$C$6:$I$6,D7) -> 0 | BO7: =COUNTIF(pick!$C$6:$I$6,E7) -> 0 | BP7: =COUNTIF(pick!$C$6:$I$6,F7) -> 1 | BQ7: =COUNTIF(pick!$C$6:$I$6,G7) -> 0 | BR7: =COUNTIF(pick!$C$6:$I$6,H7) -> 0 | BS7: =COUNTIF(pick!$C$6:$I$6,I7) -> 0 | BT7: =COUNTIF(pick!$C$6:$I$6,J7) -> 0 | BU7: =COUNTIF(pick!$C$6:$I$6,K7) -> 0 | BV7: =SUM(BM7:BS7) -> 1 | BW7: =SUM(BT7:BU7) -> 0 | BX7: =SUM(BM7:BU7) -> 1
A8: 第6回 | B8: 2013年5月10日 | C8: 05 | D8: 15 | E8: 19 | F8: 23 | G8: 30 | H8: 34 | I8: 35 | J8: 06 | K8: 25 | M8: =COUNTIF(pick!$C$2:$I$2,C8) -> 1 | N8: =COUNTIF(pick!$C$2:$I$2,D8) -> 0 | O8: =COUNTIF(pick!$C$2:$I$2,E8) -> 0 | P8: =COUNTIF(pick!$C$2:$I$2,F8) -> 0 | Q8: =COUNTIF(pick!$C$2:$I$2,G8) -> 0 | R8: =COUNTIF(pick!$C$2:$I$2,H8) -> 0 | S8: =COUNTIF(pick!$C$2:$I$2,I8) -> 0 | T8: =COUNTIF(pick!$C$2:$I$2,J8) -> 1 | U8: =COUNTIF(pick!$C$2:$I$2,K8) -> 0 | V8: =SUM(M8:S8) -> 1 | W8: =SUM(T8:U8) -> 1 | X8: =SUM(M8:U8) -> 2 | Z8: =COUNTIF(pick!$C$3:$I$3,C8) -> 1 | AA8: =COUNTIF(pick!$C$3:$I$3,D8) -> 0 | AB8: =COUNTIF(pick!$C$3:$I$3,E8) -> 0 | AC8: =COUNTIF(pick!$C$3:$I$3,F8) -> 0 | AD8: =COUNTIF(pick!$C$3:$I$3,G8) -> 0 | AE8: =COUNTIF(pick!$C$3:$I$3,H8) -> 0 | AF8: =COUNTIF(pick!$C$3:$I$3,I8) -> 0 | AG8: =COUNTIF(pick!$C$3:$I$3,J8) -> 1 | AH8: =COUNTIF(pick!$C$3:$I$3,K8) -> 0 | AI8: =SUM(Z8:AF8) -> 1 | AJ8: =SUM(AG8:AH8) -> 1 | AK8: =SUM(Z8:AH8) -> 2 | AM8: =COUNTIF(pick!$C$4:$I$4,C8) -> 1 | AN8: =COUNTIF(pick!$C$4:$I$4,D8) -> 0 | AO8: =COUNTIF(pick!$C$4:$I$4,E8) -> 0 | AP8: =COUNTIF(pick!$C$4:$I$4,F8) -> 0 | AQ8: =COUNTIF(pick!$C$4:$I$4,G8) -> 0 | AR8: =COUNTIF(pick!$C$4:$I$4,H8) -> 0 | AS8: =COUNTIF(pick!$C$4:$I$4,I8) -> 0 | AT8: =COUNTIF(pick!$C$4:$I$4,J8) -> 1 | AU8: =COUNTIF(pick!$C$4:$I$4,K8) -> 0 | AV8: =SUM(AM8:AS8) -> 1 | AW8: =SUM(AT8:AU8) -> 1 | AX8: =SUM(AM8:AU8) -> 2 | AZ8: =COUNTIF(pick!$C$5:$I$5,C8) -> 1 | BA8: =COUNTIF(pick!$C$5:$I$5,D8) -> 0 | BB8: =COUNTIF(pick!$C$5:$I$5,E8) -> 0 | BC8: =COUNTIF(pick!$C$5:$I$5,F8) -> 0 | BD8: =COUNTIF(pick!$C$5:$I$5,G8) -> 0 | BE8: =COUNTIF(pick!$C$5:$I$5,H8) -> 0 | BF8: =COUNTIF(pick!$C$5:$I$5,I8) -> 0 | BG8: =COUNTIF(pick!$C$5:$I$5,J8) -> 1 | BH8: =COUNTIF(pick!$C$5:$I$5,K8) -> 0 | BI8: =SUM(AZ8:BF8) -> 1 | BJ8: =SUM(BG8:BH8) -> 1 | BK8: =SUM(AZ8:BH8) -> 2 | BM8: =COUNTIF(pick!$C$6:$I$6,C8) -> 1 | BN8: =COUNTIF(pick!$C$6:$I$6,D8) -> 0 | BO8: =COUNTIF(pick!$C$6:$I$6,E8) -> 0 | BP8: =COUNTIF(pick!$C$6:$I$6,F8) -> 0 | BQ8: =COUNTIF(pick!$C$6:$I$6,G8) -> 0 | BR8: =COUNTIF(pick!$C$6:$I$6,H8) -> 0 | BS8: =COUNTIF(pick!$C$6:$I$6,I8) -> 0 | BT8: =COUNTIF(pick!$C$6:$I$6,J8) -> 1 | BU8: =COUNTIF(pick!$C$6:$I$6,K8) -> 0 | BV8: =SUM(BM8:BS8) -> 1 | BW8: =SUM(BT8:BU8) -> 1 | BX8: =SUM(BM8:BU8) -> 2
A9: 第7回 | B9: 2013年5月17日 | C9: 01 | D9: 03 | E9: 05 | F9: 07 | G9: 27 | H9: 29 | I9: 33 | J9: 06 | K9: 15 | M9: =COUNTIF(pick!$C$2:$I$2,C9) -> 1 | N9: =COUNTIF(pick!$C$2:$I$2,D9) -> 1 | O9: =COUNTIF(pick!$C$2:$I$2,E9) -> 1 | P9: =COUNTIF(pick!$C$2:$I$2,F9) -> 1 | Q9: =COUNTIF(pick!$C$2:$I$2,G9) -> 0 | R9: =COUNTIF(pick!$C$2:$I$2,H9) -> 0 | S9: =COUNTIF(pick!$C$2:$I$2,I9) -> 0 | T9: =COUNTIF(pick!$C$2:$I$2,J9) -> 1 | U9: =COUNTIF(pick!$C$2:$I$2,K9) -> 0 | V9: =SUM(M9:S9) -> 4 | W9: =SUM(T9:U9) -> 1 | X9: =SUM(M9:U9) -> 5 | Z9: =COUNTIF(pick!$C$3:$I$3,C9) -> 0 | AA9: =COUNTIF(pick!$C$3:$I$3,D9) -> 1 | AB9: =COUNTIF(pick!$C$3:$I$3,E9) -> 1 | AC9: =COUNTIF(pick!$C$3:$I$3,F9) -> 1 | AD9: =COUNTIF(pick!$C$3:$I$3,G9) -> 0 | AE9: =COUNTIF(pick!$C$3:$I$3,H9) -> 0 | AF9: =COUNTIF(pick!$C$3:$I$3,I9) -> 0 | AG9: =COUNTIF(pick!$C$3:$I$3,J9) -> 1 | AH9: =COUNTIF(pick!$C$3:$I$3,K9) -> 0 | AI9: =SUM(Z9:AF9) -> 3 | AJ9: =SUM(AG9:AH9) -> 1 | AK9: =SUM(Z9:AH9) -> 4 | AM9: =COUNTIF(pick!$C$4:$I$4,C9) -> 0 | AN9: =COUNTIF(pick!$C$4:$I$4,D9) -> 1 | AO9: =COUNTIF(pick!$C$4:$I$4,E9) -> 1 | AP9: =COUNTIF(pick!$C$4:$I$4,F9) -> 1 | AQ9: =COUNTIF(pick!$C$4:$I$4,G9) -> 0 | AR9: =COUNTIF(pick!$C$4:$I$4,H9) -> 0 | AS9: =COUNTIF(pick!$C$4:$I$4,I9) -> 0 | AT9: =COUNTIF(pick!$C$4:$I$4,J9) -> 1 | AU9: =COUNTIF(pick!$C$4:$I$4,K9) -> 0 | AV9: =SUM(AM9:AS9) -> 3 | AW9: =SUM(AT9:AU9) -> 1 | AX9: =SUM(AM9:AU9) -> 4 | AZ9: =COUNTIF(pick!$C$5:$I$5,C9) -> 0 | BA9: =COUNTIF(pick!$C$5:$I$5,D9) -> 0 | BB9: =COUNTIF(pick!$C$5:$I$5,E9) -> 1 | BC9: =COUNTIF(pick!$C$5:$I$5,F9) -> 1 | BD9: =COUNTIF(pick!$C$5:$I$5,G9) -> 0 | BE9: =COUNTIF(pick!$C$5:$I$5,H9) -> 0 | BF9: =COUNTIF(pick!$C$5:$I$5,I9) -> 0 | BG9: =COUNTIF(pick!$C$5:$I$5,J9) -> 1 | BH9: =COUNTIF(pick!$C$5:$I$5,K9) -> 0 | BI9: =SUM(AZ9:BF9) -> 2 | BJ9: =SUM(BG9:BH9) -> 1 | BK9: =SUM(AZ9:BH9) -> 3 | BM9: =COUNTIF(pick!$C$6:$I$6,C9) -> 0 | BN9: =COUNTIF(pick!$C$6:$I$6,D9) -> 0 | BO9: =COUNTIF(pick!$C$6:$I$6,E9) -> 1 | BP9: =COUNTIF(pick!$C$6:$I$6,F9) -> 1 | BQ9: =COUNTIF(pick!$C$6:$I$6,G9) -> 0 | BR9: =COUNTIF(pick!$C$6:$I$6,H9) -> 0 | BS9: =COUNTIF(pick!$C$6:$I$6,I9) -> 0 | BT9: =COUNTIF(pick!$C$6:$I$6,J9) -> 1 | BU9: =COUNTIF(pick!$C$6:$I$6,K9) -> 0 | BV9: =SUM(BM9:BS9) -> 2 | BW9: =SUM(BT9:BU9) -> 1 | BX9: =SUM(BM9:BU9) -> 3
A10: 第8回 | B10: 2013年5月24日 | C10: 02 | D10: 21 | E10: 28 | F10: 29 | G10: 30 | H10: 32 | I10: 36 | J10: 06 | K10: 08 | M10: =COUNTIF(pick!$C$2:$I$2,C10) -> 1 | N10: =COUNTIF(pick!$C$2:$I$2,D10) -> 0 | O10: =COUNTIF(pick!$C$2:$I$2,E10) -> 0 | P10: =COUNTIF(pick!$C$2:$I$2,F10) -> 0 | Q10: =COUNTIF(pick!$C$2:$I$2,G10) -> 0 | R10: =COUNTIF(pick!$C$2:$I$2,H10) -> 0 | S10: =COUNTIF(pick!$C$2:$I$2,I10) -> 0 | T10: =COUNTIF(pick!$C$2:$I$2,J10) -> 1 | U10: =COUNTIF(pick!$C$2:$I$2,K10) -> 0 | V10: =SUM(M10:S10) -> 1 | W10: =SUM(T10:U10) -> 1 | X10: =SUM(M10:U10) -> 2 | Z10: =COUNTIF(pick!$C$3:$I$3,C10) -> 1 | AA10: =COUNTIF(pick!$C$3:$I$3,D10) -> 0 | AB10: =COUNTIF(pick!$C$3:$I$3,E10) -> 0 | AC10: =COUNTIF(pick!$C$3:$I$3,F10) -> 0 | AD10: =COUNTIF(pick!$C$3:$I$3,G10) -> 0 | AE10: =COUNTIF(pick!$C$3:$I$3,H10) -> 0 | AF10: =COUNTIF(pick!$C$3:$I$3,I10) -> 0 | AG10: =COUNTIF(pick!$C$3:$I$3,J10) -> 1 | AH10: =COUNTIF(pick!$C$3:$I$3,K10) -> 1 | AI10: =SUM(Z10:AF10) -> 1 | AJ10: =SUM(AG10:AH10) -> 2 | AK10: =SUM(Z10:AH10) -> 3 | AM10: =COUNTIF(pick!$C$4:$I$4,C10) -> 0 | AN10: =COUNTIF(pick!$C$4:$I$4,D10) -> 0 | AO10: =COUNTIF(pick!$C$4:$I$4,E10) -> 0 | AP10: =COUNTIF(pick!$C$4:$I$4,F10) -> 0 | AQ10: =COUNTIF(pick!$C$4:$I$4,G10) -> 0 | AR10: =COUNTIF(pick!$C$4:$I$4,H10) -> 0 | AS10: =COUNTIF(pick!$C$4:$I$4,I10) -> 0 | AT10: =COUNTIF(pick!$C$4:$I$4,J10) -> 1 | AU10: =COUNTIF(pick!$C$4:$I$4,K10) -> 1 | AV10: =SUM(AM10:AS10) -> 0 | AW10: =SUM(AT10:AU10) -> 2 | AX10: =SUM(AM10:AU10) -> 2 | AZ10: =COUNTIF(pick!$C$5:$I$5,C10) -> 0 | BA10: =COUNTIF(pick!$C$5:$I$5,D10) -> 0 | BB10: =COUNTIF(pick!$C$5:$I$5,E10) -> 0 | BC10: =COUNTIF(pick!$C$5:$I$5,F10) -> 0 | BD10: =COUNTIF(pick!$C$5:$I$5,G10) -> 0 | BE10: =COUNTIF(pick!$C$5:$I$5,H10) -> 0 | BF10: =COUNTIF(pick!$C$5:$I$5,I10) -> 0 | BG10: =COUNTIF(pick!$C$5:$I$5,J10) -> 1 | BH10: =COUNTIF(pick!$C$5:$I$5,K10) -> 1 | BI10: =SUM(AZ10:BF10) -> 0 | BJ10: =SUM(BG10:BH10) -> 2 | BK10: =SUM(AZ10:BH10) -> 2 | BM10: =COUNTIF(pick!$C$6:$I$6,C10) -> 0 | BN10: =COUNTIF(pick!$C$6:$I$6,D10) -> 0 | BO10: =COUNTIF(pick!$C$6:$I$6,E10) -> 0 | BP10: =COUNTIF(pick!$C$6:$I$6,F10) -> 0 | BQ10: =COUNTIF(pick!$C$6:$I$6,G10) -> 0 | BR10: =COUNTIF(pick!$C$6:$I$6,H10) -> 0 | BS10: =COUNTIF(pick!$C$6:$I$6,I10) -> 0 | BT10: =COUNTIF(pick!$C$6:$I$6,J10) -> 1 | BU10: =COUNTIF(pick!$C$6:$I$6,K10) -> 1 | BV10: =SUM(BM10:BS10) -> 0 | BW10: =SUM(BT10:BU10) -> 2 | BX10: =SUM(BM10:BU10) -> 2
A11: 第9回 | B11: 2013年5月31日 | C11: 03 | D11: 04 | E11: 15 | F11: 23 | G11: 27 | H11: 30 | I11: 36 | J11: 13 | K11: 35 | M11: =COUNTIF(pick!$C$2:$I$2,C11) -> 1 | N11: =COUNTIF(pick!$C$2:$I$2,D11) -> 1 | O11: =COUNTIF(pick!$C$2:$I$2,E11) -> 0 | P11: =COUNTIF(pick!$C$2:$I$2,F11) -> 0 | Q11: =COUNTIF(pick!$C$2:$I$2,G11) -> 0 | R11: =COUNTIF(pick!$C$2:$I$2,H11) -> 0 | S11: =COUNTIF(pick!$C$2:$I$2,I11) -> 0 | T11: =COUNTIF(pick!$C$2:$I$2,J11) -> 0 | U11: =COUNTIF(pick!$C$2:$I$2,K11) -> 0 | V11: =SUM(M11:S11) -> 2 | W11: =SUM(T11:U11) -> 0 | X11: =SUM(M11:U11) -> 2 | Z11: =COUNTIF(pick!$C$3:$I$3,C11) -> 1 | AA11: =COUNTIF(pick!$C$3:$I$3,D11) -> 1 | AB11: =COUNTIF(pick!$C$3:$I$3,E11) -> 0 | AC11: =COUNTIF(pick!$C$3:$I$3,F11) -> 0 | AD11: =COUNTIF(pick!$C$3:$I$3,G11) -> 0 | AE11: =COUNTIF(pick!$C$3:$I$3,H11) -> 0 | AF11: =COUNTIF(pick!$C$3:$I$3,I11) -> 0 | AG11: =COUNTIF(pick!$C$3:$I$3,J11) -> 0 | AH11: =COUNTIF(pick!$C$3:$I$3,K11) -> 0 | AI11: =SUM(Z11:AF11) -> 2 | AJ11: =SUM(AG11:AH11) -> 0 | AK11: =SUM(Z11:AH11) -> 2 | AM11: =COUNTIF(pick!$C$4:$I$4,C11) -> 1 | AN11: =COUNTIF(pick!$C$4:$I$4,D11) -> 1 | AO11: =COUNTIF(pick!$C$4:$I$4,E11) -> 0 | AP11: =COUNTIF(pick!$C$4:$I$4,F11) -> 0 | AQ11: =COUNTIF(pick!$C$4:$I$4,G11) -> 0 | AR11: =COUNTIF(pick!$C$4:$I$4,H11) -> 0 | AS11: =COUNTIF(pick!$C$4:$I$4,I11) -> 0 | AT11: =COUNTIF(pick!$C$4:$I$4,J11) -> 0 | AU11: =COUNTIF(pick!$C$4:$I$4,K11) -> 0 | AV11: =SUM(AM11:AS11) -> 2 | AW11: =SUM(AT11:AU11) -> 0 | AX11: =SUM(AM11:AU11) -> 2 | AZ11: =COUNTIF(pick!$C$5:$I$5,C11) -> 0 | BA11: =COUNTIF(pick!$C$5:$I$5,D11) -> 1 | BB11: =COUNTIF(pick!$C$5:$I$5,E11) -> 0 | BC11: =COUNTIF(pick!$C$5:$I$5,F11) -> 0 | BD11: =COUNTIF(pick!$C$5:$I$5,G11) -> 0 | BE11: =COUNTIF(pick!$C$5:$I$5,H11) -> 0 | BF11: =COUNTIF(pick!$C$5:$I$5,I11) -> 0 | BG11: =COUNTIF(pick!$C$5:$I$5,J11) -> 0 | BH11: =COUNTIF(pick!$C$5:$I$5,K11) -> 0 | BI11: =SUM(AZ11:BF11) -> 1 | BJ11: =SUM(BG11:BH11) -> 0 | BK11: =SUM(AZ11:BH11) -> 1 | BM11: =COUNTIF(pick!$C$6:$I$6,C11) -> 0 | BN11: =COUNTIF(pick!$C$6:$I$6,D11) -> 0 | BO11: =COUNTIF(pick!$C$6:$I$6,E11) -> 0 | BP11: =COUNTIF(pick!$C$6:$I$6,F11) -> 0 | BQ11: =COUNTIF(pick!$C$6:$I$6,G11) -> 0 | BR11: =COUNTIF(pick!$C$6:$I$6,H11) -> 0 | BS11: =COUNTIF(pick!$C$6:$I$6,I11) -> 0 | BT11: =COUNTIF(pick!$C$6:$I$6,J11) -> 0 | BU11: =COUNTIF(pick!$C$6:$I$6,K11) -> 0 | BV11: =SUM(BM11:BS11) -> 0 | BW11: =SUM(BT11:BU11) -> 0 | BX11: =SUM(BM11:BU11) -> 0
A12: 第10回 | B12: 2013年6月7日 | C12: 01 | D12: 02 | E12: 03 | F12: 06 | G12: 24 | H12: 28 | I12: 30 | J12: 16 | K12: 20 | M12: =COUNTIF(pick!$C$2:$I$2,C12) -> 1 | N12: =COUNTIF(pick!$C$2:$I$2,D12) -> 1 | O12: =COUNTIF(pick!$C$2:$I$2,E12) -> 1 | P12: =COUNTIF(pick!$C$2:$I$2,F12) -> 1 | Q12: =COUNTIF(pick!$C$2:$I$2,G12) -> 0 | R12: =COUNTIF(pick!$C$2:$I$2,H12) -> 0 | S12: =COUNTIF(pick!$C$2:$I$2,I12) -> 0 | T12: =COUNTIF(pick!$C$2:$I$2,J12) -> 0 | U12: =COUNTIF(pick!$C$2:$I$2,K12) -> 0 | V12: =SUM(M12:S12) -> 4 | W12: =SUM(T12:U12) -> 0 | X12: =SUM(M12:U12) -> 4 | Z12: =COUNTIF(pick!$C$3:$I$3,C12) -> 0 | AA12: =COUNTIF(pick!$C$3:$I$3,D12) -> 1 | AB12: =COUNTIF(pick!$C$3:$I$3,E12) -> 1 | AC12: =COUNTIF(pick!$C$3:$I$3,F12) -> 1 | AD12: =COUNTIF(pick!$C$3:$I$3,G12) -> 0 | AE12: =COUNTIF(pick!$C$3:$I$3,H12) -> 0 | AF12: =COUNTIF(pick!$C$3:$I$3,I12) -> 0 | AG12: =COUNTIF(pick!$C$3:$I$3,J12) -> 0 | AH12: =COUNTIF(pick!$C$3:$I$3,K12) -> 0 | AI12: =SUM(Z12:AF12) -> 3 | AJ12: =SUM(AG12:AH12) -> 0 | AK12: =SUM(Z12:AH12) -> 3 | AM12: =COUNTIF(pick!$C$4:$I$4,C12) -> 0 | AN12: =COUNTIF(pick!$C$4:$I$4,D12) -> 0 | AO12: =COUNTIF(pick!$C$4:$I$4,E12) -> 1 | AP12: =COUNTIF(pick!$C$4:$I$4,F12) -> 1 | AQ12: =COUNTIF(pick!$C$4:$I$4,G12) -> 0 | AR12: =COUNTIF(pick!$C$4:$I$4,H12) -> 0 | AS12: =COUNTIF(pick!$C$4:$I$4,I12) -> 0 | AT12: =COUNTIF(pick!$C$4:$I$4,J12) -> 0 | AU12: =COUNTIF(pick!$C$4:$I$4,K12) -> 0 | AV12: =SUM(AM12:AS12) -> 2 | AW12: =SUM(AT12:AU12) -> 0 | AX12: =SUM(AM12:AU12) -> 2 | AZ12: =COUNTIF(pick!$C$5:$I$5,C12) -> 0 | BA12: =COUNTIF(pick!$C$5:$I$5,D12) -> 0 | BB12: =COUNTIF(pick!$C$5:$I$5,E12) -> 0 | BC12: =COUNTIF(pick!$C$5:$I$5,F12) -> 1 | BD12: =COUNTIF(pick!$C$5:$I$5,G12) -> 0 | BE12: =COUNTIF(pick!$C$5:$I$5,H12) -> 0 | BF12: =COUNTIF(pick!$C$5:$I$5,I12) -> 0 | BG12: =COUNTIF(pick!$C$5:$I$5,J12) -> 0 | BH12: =COUNTIF(pick!$C$5:$I$5,K12) -> 0 | BI12: =SUM(AZ12:BF12) -> 1 | BJ12: =SUM(BG12:BH12) -> 0 | BK12: =SUM(AZ12:BH12) -> 1 | BM12: =COUNTIF(pick!$C$6:$I$6,C12) -> 0 | BN12: =COUNTIF(pick!$C$6:$I$6,D12) -> 0 | BO12: =COUNTIF(pick!$C$6:$I$6,E12) -> 0 | BP12: =COUNTIF(pick!$C$6:$I$6,F12) -> 1 | BQ12: =COUNTIF(pick!$C$6:$I$6,G12) -> 0 | BR12: =COUNTIF(pick!$C$6:$I$6,H12) -> 0 | BS12: =COUNTIF(pick!$C$6:$I$6,I12) -> 0 | BT12: =COUNTIF(pick!$C$6:$I$6,J12) -> 0 | BU12: =COUNTIF(pick!$C$6:$I$6,K12) -> 0 | BV12: =SUM(BM12:BS12) -> 1 | BW12: =SUM(BT12:BU12) -> 0 | BX12: =SUM(BM12:BU12) -> 1
A13: 第11回 | B13: 2013年6月14日 | C13: 09 | D13: 15 | E13: 26 | F13: 29 | G13: 32 | H13: 34 | I13: 36 | J13: 14 | K13: 35 | M13: =COUNTIF(pick!$C$2:$I$2,C13) -> 0 | N13: =COUNTIF(pick!$C$2:$I$2,D13) -> 0 | O13: =COUNTIF(pick!$C$2:$I$2,E13) -> 0 | P13: =COUNTIF(pick!$C$2:$I$2,F13) -> 0 | Q13: =COUNTIF(pick!$C$2:$I$2,G13) -> 0 | R13: =COUNTIF(pick!$C$2:$I$2,H13) -> 0 | S13: =COUNTIF(pick!$C$2:$I$2,I13) -> 0 | T13: =COUNTIF(pick!$C$2:$I$2,J13) -> 0 | U13: =COUNTIF(pick!$C$2:$I$2,K13) -> 0 | V13: =SUM(M13:S13) -> 0 | W13: =SUM(T13:U13) -> 0 | X13: =SUM(M13:U13) -> 0 | Z13: =COUNTIF(pick!$C$3:$I$3,C13) -> 0 | AA13: =COUNTIF(pick!$C$3:$I$3,D13) -> 0 | AB13: =COUNTIF(pick!$C$3:$I$3,E13) -> 0 | AC13: =COUNTIF(pick!$C$3:$I$3,F13) -> 0 | AD13: =COUNTIF(pick!$C$3:$I$3,G13) -> 0 | AE13: =COUNTIF(pick!$C$3:$I$3,H13) -> 0 | AF13: =COUNTIF(pick!$C$3:$I$3,I13) -> 0 | AG13: =COUNTIF(pick!$C$3:$I$3,J13) -> 0 | AH13: =COUNTIF(pick!$C$3:$I$3,K13) -> 0 | AI13: =SUM(Z13:AF13) -> 0 | AJ13: =SUM(AG13:AH13) -> 0 | AK13: =SUM(Z13:AH13) -> 0 | AM13: =COUNTIF(pick!$C$4:$I$4,C13) -> 1 | AN13: =COUNTIF(pick!$C$4:$I$4,D13) -> 0 | AO13: =COUNTIF(pick!$C$4:$I$4,E13) -> 0 | AP13: =COUNTIF(pick!$C$4:$I$4,F13) -> 0 | AQ13: =COUNTIF(pick!$C$4:$I$4,G13) -> 0 | AR13: =COUNTIF(pick!$C$4:$I$4,H13) -> 0 | AS13: =COUNTIF(pick!$C$4:$I$4,I13) -> 0 | AT13: =COUNTIF(pick!$C$4:$I$4,J13) -> 0 | AU13: =COUNTIF(pick!$C$4:$I$4,K13) -> 0 | AV13: =SUM(AM13:AS13) -> 1 | AW13: =SUM(AT13:AU13) -> 0 | AX13: =SUM(AM13:AU13) -> 1 | AZ13: =COUNTIF(pick!$C$5:$I$5,C13) -> 1 | BA13: =COUNTIF(pick!$C$5:$I$5,D13) -> 0 | BB13: =COUNTIF(pick!$C$5:$I$5,E13) -> 0 | BC13: =COUNTIF(pick!$C$5:$I$5,F13) -> 0 | BD13: =COUNTIF(pick!$C$5:$I$5,G13) -> 0 | BE13: =COUNTIF(pick!$C$5:$I$5,H13) -> 0 | BF13: =COUNTIF(pick!$C$5:$I$5,I13) -> 0 | BG13: =COUNTIF(pick!$C$5:$I$5,J13) -> 0 | BH13: =COUNTIF(pick!$C$5:$I$5,K13) -> 0 | BI13: =SUM(AZ13:BF13) -> 1 | BJ13: =SUM(BG13:BH13) -> 0 | BK13: =SUM(AZ13:BH13) -> 1 | BM13: =COUNTIF(pick!$C$6:$I$6,C13) -> 1 | BN13: =COUNTIF(pick!$C$6:$I$6,D13) -> 0 | BO13: =COUNTIF(pick!$C$6:$I$6,E13) -> 0 | BP13: =COUNTIF(pick!$C$6:$I$6,F13) -> 0 | BQ13: =COUNTIF(pick!$C$6:$I$6,G13) -> 0 | BR13: =COUNTIF(pick!$C$6:$I$6,H13) -> 0 | BS13: =COUNTIF(pick!$C$6:$I$6,I13) -> 0 | BT13: =COUNTIF(pick!$C$6:$I$6,J13) -> 0 | BU13: =COUNTIF(pick!$C$6:$I$6,K13) -> 0 | BV13: =SUM(BM13:BS13) -> 1 | BW13: =SUM(BT13:BU13) -> 0 | BX13: =SUM(BM13:BU13) -> 1
A14: 第12回 | B14: 2013年6月21日 | C14: 11 | D14: 12 | E14: 14 | F14: 19 | G14: 26 | H14: 27 | I14: 33 | J14: 24 | K14: 32 | M14: =COUNTIF(pick!$C$2:$I$2,C14) -> 0 | N14: =COUNTIF(pick!$C$2:$I$2,D14) -> 0 | O14: =COUNTIF(pick!$C$2:$I$2,E14) -> 0 | P14: =COUNTIF(pick!$C$2:$I$2,F14) -> 0 | Q14: =COUNTIF(pick!$C$2:$I$2,G14) -> 0 | R14: =COUNTIF(pick!$C$2:$I$2,H14) -> 0 | S14: =COUNTIF(pick!$C$2:$I$2,I14) -> 0 | T14: =COUNTIF(pick!$C$2:$I$2,J14) -> 0 | U14: =COUNTIF(pick!$C$2:$I$2,K14) -> 0 | V14: =SUM(M14:S14) -> 0 | W14: =SUM(T14:U14) -> 0 | X14: =SUM(M14:U14) -> 0 | Z14: =COUNTIF(pick!$C$3:$I$3,C14) -> 0 | AA14: =COUNTIF(pick!$C$3:$I$3,D14) -> 0 | AB14: =COUNTIF(pick!$C$3:$I$3,E14) -> 0 | AC14: =COUNTIF(pick!$C$3:$I$3,F14) -> 0 | AD14: =COUNTIF(pick!$C$3:$I$3,G14) -> 0 | AE14: =COUNTIF(pick!$C$3:$I$3,H14) -> 0 | AF14: =COUNTIF(pick!$C$3:$I$3,I14) -> 0 | AG14: =COUNTIF(pick!$C$3:$I$3,J14) -> 0 | AH14: =COUNTIF(pick!$C$3:$I$3,K14) -> 0 | AI14: =SUM(Z14:AF14) -> 0 | AJ14: =SUM(AG14:AH14) -> 0 | AK14: =SUM(Z14:AH14) -> 0 | AM14: =COUNTIF(pick!$C$4:$I$4,C14) -> 0 | AN14: =COUNTIF(pick!$C$4:$I$4,D14) -> 0 | AO14: =COUNTIF(pick!$C$4:$I$4,E14) -> 0 | AP14: =COUNTIF(pick!$C$4:$I$4,F14) -> 0 | AQ14: =COUNTIF(pick!$C$4:$I$4,G14) -> 0 | AR14: =COUNTIF(pick!$C$4:$I$4,H14) -> 0 | AS14: =COUNTIF(pick!$C$4:$I$4,I14) -> 0 | AT14: =COUNTIF(pick!$C$4:$I$4,J14) -> 0 | AU14: =COUNTIF(pick!$C$4:$I$4,K14) -> 0 | AV14: =SUM(AM14:AS14) -> 0 | AW14: =SUM(AT14:AU14) -> 0 | AX14: =SUM(AM14:AU14) -> 0 | AZ14: =COUNTIF(pick!$C$5:$I$5,C14) -> 0 | BA14: =COUNTIF(pick!$C$5:$I$5,D14) -> 0 | BB14: =COUNTIF(pick!$C$5:$I$5,E14) -> 0 | BC14: =COUNTIF(pick!$C$5:$I$5,F14) -> 0 | BD14: =COUNTIF(pick!$C$5:$I$5,G14) -> 0 | BE14: =COUNTIF(pick!$C$5:$I$5,H14) -> 0 | BF14: =COUNTIF(pick!$C$5:$I$5,I14) -> 0 | BG14: =COUNTIF(pick!$C$5:$I$5,J14) -> 0 | BH14: =COUNTIF(pick!$C$5:$I$5,K14) -> 0 | BI14: =SUM(AZ14:BF14) -> 0 | BJ14: =SUM(BG14:BH14) -> 0 | BK14: =SUM(AZ14:BH14) -> 0 | BM14: =COUNTIF(pick!$C$6:$I$6,C14) -> 1 | BN14: =COUNTIF(pick!$C$6:$I$6,D14) -> 0 | BO14: =COUNTIF(pick!$C$6:$I$6,E14) -> 0 | BP14: =COUNTIF(pick!$C$6:$I$6,F14) -> 0 | BQ14: =COUNTIF(pick!$C$6:$I$6,G14) -> 0 | BR14: =COUNTIF(pick!$C$6:$I$6,H14) -> 0 | BS14: =COUNTIF(pick!$C$6:$I$6,I14) -> 0 | BT14: =COUNTIF(pick!$C$6:$I$6,J14) -> 0 | BU14: =COUNTIF(pick!$C$6:$I$6,K14) -> 0 | BV14: =SUM(BM14:BS14) -> 1 | BW14: =SUM(BT14:BU14) -> 0 | BX14: =SUM(BM14:BU14) -> 1
... A678: 第676回 | B678: 2026年5月8日 | C678: 02 | D678: 06 | E678: 15 | F678: 19 | G678: 20 | H678: 22 | I678: 27 | J678: 31 | K678: 33 | M678: =COUNTIF(pick!$C$2:$I$2,C678) -> 1 | N678: =COUNTIF(pick!$C$2:$I$2,D678) -> 1 | O678: =COUNTIF(pick!$C$2:$I$2,E678) -> 0 | P678: =COUNTIF(pick!$C$2:$I$2,F678) -> 0 | Q678: =COUNTIF(pick!$C$2:$I$2,G678) -> 0 | R678: =COUNTIF(pick!$C$2:$I$2,H678) -> 0 | S678: =COUNTIF(pick!$C$2:$I$2,I678) -> 0 | T678: =COUNTIF(pick!$C$2:$I$2,J678) -> 0 | U678: =COUNTIF(pick!$C$2:$I$2,K678) -> 0 | V678: =SUM(M678:S678) -> 2 | W678: =SUM(T678:U678) -> 0 | X678: =SUM(M678:U678) -> 2 | Z678: =COUNTIF(pick!$C$3:$I$3,C678) -> 1 | AA678: =COUNTIF(pick!$C$3:$I$3,D678) -> 1 | AB678: =COUNTIF(pick!$C$3:$I$3,E678) -> 0 | AC678: =COUNTIF(pick!$C$3:$I$3,F678) -> 0 | AD678: =COUNTIF(pick!$C$3:$I$3,G678) -> 0 | AE678: =COUNTIF(pick!$C$3:$I$3,H678) -> 0 | AF678: =COUNTIF(pick!$C$3:$I$3,I678) -> 0 | AG678: =COUNTIF(pick!$C$3:$I$3,J678) -> 0 | AH678: =COUNTIF(pick!$C$3:$I$3,K678) -> 0 | AI678: =SUM(Z678:AF678) -> 2 | AJ678: =SUM(AG678:AH678) -> 0 | AK678: =SUM(Z678:AH678) -> 2 | AM678: =COUNTIF(pick!$C$4:$I$4,C678) -> 0 | AN678: =COUNTIF(pick!$C$4:$I$4,D678) -> 1 | AO678: =COUNTIF(pick!$C$4:$I$4,E678) -> 0 | AP678: =COUNTIF(pick!$C$4:$I$4,F678) -> 0 | AQ678: =COUNTIF(pick!$C$4:$I$4,G678) -> 0 | AR678: =COUNTIF(pick!$C$4:$I$4,H678) -> 0 | AS678: =COUNTIF(pick!$C$4:$I$4,I678) -> 0 | AT678: =COUNTIF(pick!$C$4:$I$4,J678) -> 0 | AU678: =COUNTIF(pick!$C$4:$I$4,K678) -> 0 | AV678: =SUM(AM678:AS678) -> 1 | AW678: =SUM(AT678:AU678) -> 0 | AX678: =SUM(AM678:AU678) -> 1 | AZ678: =COUNTIF(pick!$C$5:$I$5,C678) -> 0 | BA678: =COUNTIF(pick!$C$5:$I$5,D678) -> 1 | BB678: =COUNTIF(pick!$C$5:$I$5,E678) -> 0 | BC678: =COUNTIF(pick!$C$5:$I$5,F678) -> 0 | BD678: =COUNTIF(pick!$C$5:$I$5,G678) -> 0 | BE678: =COUNTIF(pick!$C$5:$I$5,H678) -> 0 | BF678: =COUNTIF(pick!$C$5:$I$5,I678) -> 0 | BG678: =COUNTIF(pick!$C$5:$I$5,J678) -> 0 | BH678: =COUNTIF(pick!$C$5:$I$5,K678) -> 0 | BI678: =SUM(AZ678:BF678) -> 1 | BJ678: =SUM(BG678:BH678) -> 0 | BK678: =SUM(AZ678:BH678) -> 1 | BM678: =COUNTIF(pick!$C$6:$I$6,C678) -> 0 | BN678: =COUNTIF(pick!$C$6:$I$6,D678) -> 1 | BO678: =COUNTIF(pick!$C$6:$I$6,E678) -> 0 | BP678: =COUNTIF(pick!$C$6:$I$6,F678) -> 0 | BQ678: =COUNTIF(pick!$C$6:$I$6,G678) -> 0 | BR678: =COUNTIF(pick!$C$6:$I$6,H678) -> 0 | BS678: =COUNTIF(pick!$C$6:$I$6,I678) -> 0 | BT678: =COUNTIF(pick!$C$6:$I$6,J678) -> 0 | BU678: =COUNTIF(pick!$C$6:$I$6,K678) -> 0 | BV678: =SUM(BM678:BS678) -> 1 | BW678: =SUM(BT678:BU678) -> 0 | BX678: =SUM(BM678:BU678) -> 1
A679: 第677回 | M679: =COUNTIF(pick!$C$2:$I$2,C679) -> 0 | N679: =COUNTIF(pick!$C$2:$I$2,D679) -> 0 | O679: =COUNTIF(pick!$C$2:$I$2,E679) -> 0 | P679: =COUNTIF(pick!$C$2:$I$2,F679) -> 0 | Q679: =COUNTIF(pick!$C$2:$I$2,G679) -> 0 | R679: =COUNTIF(pick!$C$2:$I$2,H679) -> 0 | S679: =COUNTIF(pick!$C$2:$I$2,I679) -> 0 | T679: =COUNTIF(pick!$C$2:$I$2,J679) -> 0 | U679: =COUNTIF(pick!$C$2:$I$2,K679) -> 0 | V679: =SUM(M679:S679) -> 0 | W679: =SUM(T679:U679) -> 0 | X679: =SUM(M679:U679) -> 0 | Z679: =COUNTIF(pick!$C$3:$I$3,C679) -> 0 | AA679: =COUNTIF(pick!$C$3:$I$3,D679) -> 0 | AB679: =COUNTIF(pick!$C$3:$I$3,E679) -> 0 | AC679: =COUNTIF(pick!$C$3:$I$3,F679) -> 0 | AD679: =COUNTIF(pick!$C$3:$I$3,G679) -> 0 | AE679: =COUNTIF(pick!$C$3:$I$3,H679) -> 0 | AF679: =COUNTIF(pick!$C$3:$I$3,I679) -> 0 | AG679: =COUNTIF(pick!$C$3:$I$3,J679) -> 0 | AH679: =COUNTIF(pick!$C$3:$I$3,K679) -> 0 | AI679: =SUM(Z679:AF679) -> 0 | AJ679: =SUM(AG679:AH679) -> 0 | AK679: =SUM(Z679:AH679) -> 0 | AM679: =COUNTIF(pick!$C$4:$I$4,C679) -> 0 | AN679: =COUNTIF(pick!$C$4:$I$4,D679) -> 0 | AO679: =COUNTIF(pick!$C$4:$I$4,E679) -> 0 | AP679: =COUNTIF(pick!$C$4:$I$4,F679) -> 0 | AQ679: =COUNTIF(pick!$C$4:$I$4,G679) -> 0 | AR679: =COUNTIF(pick!$C$4:$I$4,H679) -> 0 | AS679: =COUNTIF(pick!$C$4:$I$4,I679) -> 0 | AT679: =COUNTIF(pick!$C$4:$I$4,J679) -> 0 | AU679: =COUNTIF(pick!$C$4:$I$4,K679) -> 0 | AV679: =SUM(AM679:AS679) -> 0 | AW679: =SUM(AT679:AU679) -> 0 | AX679: =SUM(AM679:AU679) -> 0 | AZ679: =COUNTIF(pick!$C$5:$I$5,C679) -> 0 | BA679: =COUNTIF(pick!$C$5:$I$5,D679) -> 0 | BB679: =COUNTIF(pick!$C$5:$I$5,E679) -> 0 | BC679: =COUNTIF(pick!$C$5:$I$5,F679) -> 0 | BD679: =COUNTIF(pick!$C$5:$I$5,G679) -> 0 | BE679: =COUNTIF(pick!$C$5:$I$5,H679) -> 0 | BF679: =COUNTIF(pick!$C$5:$I$5,I679) -> 0 | BG679: =COUNTIF(pick!$C$5:$I$5,J679) -> 0 | BH679: =COUNTIF(pick!$C$5:$I$5,K679) -> 0 | BI679: =SUM(AZ679:BF679) -> 0 | BJ679: =SUM(BG679:BH679) -> 0 | BK679: =SUM(AZ679:BH679) -> 0 | BM679: =COUNTIF(pick!$C$6:$I$6,C679) -> 0 | BN679: =COUNTIF(pick!$C$6:$I$6,D679) -> 0 | BO679: =COUNTIF(pick!$C$6:$I$6,E679) -> 0 | BP679: =COUNTIF(pick!$C$6:$I$6,F679) -> 0 | BQ679: =COUNTIF(pick!$C$6:$I$6,G679) -> 0 | BR679: =COUNTIF(pick!$C$6:$I$6,H679) -> 0 | BS679: =COUNTIF(pick!$C$6:$I$6,I679) -> 0 | BT679: =COUNTIF(pick!$C$6:$I$6,J679) -> 0 | BU679: =COUNTIF(pick!$C$6:$I$6,K679) -> 0 | BV679: =SUM(BM679:BS679) -> 0 | BW679: =SUM(BT679:BU679) -> 0 | BX679: =SUM(BM679:BU679) -> 0
A680: 第678回 | M680: =COUNTIF(pick!$C$2:$I$2,C680) -> 0 | N680: =COUNTIF(pick!$C$2:$I$2,D680) -> 0 | O680: =COUNTIF(pick!$C$2:$I$2,E680) -> 0 | P680: =COUNTIF(pick!$C$2:$I$2,F680) -> 0 | Q680: =COUNTIF(pick!$C$2:$I$2,G680) -> 0 | R680: =COUNTIF(pick!$C$2:$I$2,H680) -> 0 | S680: =COUNTIF(pick!$C$2:$I$2,I680) -> 0 | T680: =COUNTIF(pick!$C$2:$I$2,J680) -> 0 | U680: =COUNTIF(pick!$C$2:$I$2,K680) -> 0 | V680: =SUM(M680:S680) -> 0 | W680: =SUM(T680:U680) -> 0 | X680: =SUM(M680:U680) -> 0 | Z680: =COUNTIF(pick!$C$3:$I$3,C680) -> 0 | AA680: =COUNTIF(pick!$C$3:$I$3,D680) -> 0 | AB680: =COUNTIF(pick!$C$3:$I$3,E680) -> 0 | AC680: =COUNTIF(pick!$C$3:$I$3,F680) -> 0 | AD680: =COUNTIF(pick!$C$3:$I$3,G680) -> 0 | AE680: =COUNTIF(pick!$C$3:$I$3,H680) -> 0 | AF680: =COUNTIF(pick!$C$3:$I$3,I680) -> 0 | AG680: =COUNTIF(pick!$C$3:$I$3,J680) -> 0 | AH680: =COUNTIF(pick!$C$3:$I$3,K680) -> 0 | AI680: =SUM(Z680:AF680) -> 0 | AJ680: =SUM(AG680:AH680) -> 0 | AK680: =SUM(Z680:AH680) -> 0 | AM680: =COUNTIF(pick!$C$4:$I$4,C680) -> 0 | AN680: =COUNTIF(pick!$C$4:$I$4,D680) -> 0 | AO680: =COUNTIF(pick!$C$4:$I$4,E680) -> 0 | AP680: =COUNTIF(pick!$C$4:$I$4,F680) -> 0 | AQ680: =COUNTIF(pick!$C$4:$I$4,G680) -> 0 | AR680: =COUNTIF(pick!$C$4:$I$4,H680) -> 0 | AS680: =COUNTIF(pick!$C$4:$I$4,I680) -> 0 | AT680: =COUNTIF(pick!$C$4:$I$4,J680) -> 0 | AU680: =COUNTIF(pick!$C$4:$I$4,K680) -> 0 | AV680: =SUM(AM680:AS680) -> 0 | AW680: =SUM(AT680:AU680) -> 0 | AX680: =SUM(AM680:AU680) -> 0 | AZ680: =COUNTIF(pick!$C$5:$I$5,C680) -> 0 | BA680: =COUNTIF(pick!$C$5:$I$5,D680) -> 0 | BB680: =COUNTIF(pick!$C$5:$I$5,E680) -> 0 | BC680: =COUNTIF(pick!$C$5:$I$5,F680) -> 0 | BD680: =COUNTIF(pick!$C$5:$I$5,G680) -> 0 | BE680: =COUNTIF(pick!$C$5:$I$5,H680) -> 0 | BF680: =COUNTIF(pick!$C$5:$I$5,I680) -> 0 | BG680: =COUNTIF(pick!$C$5:$I$5,J680) -> 0 | BH680: =COUNTIF(pick!$C$5:$I$5,K680) -> 0 | BI680: =SUM(AZ680:BF680) -> 0 | BJ680: =SUM(BG680:BH680) -> 0 | BK680: =SUM(AZ680:BH680) -> 0 | BM680: =COUNTIF(pick!$C$6:$I$6,C680) -> 0 | BN680: =COUNTIF(pick!$C$6:$I$6,D680) -> 0 | BO680: =COUNTIF(pick!$C$6:$I$6,E680) -> 0 | BP680: =COUNTIF(pick!$C$6:$I$6,F680) -> 0 | BQ680: =COUNTIF(pick!$C$6:$I$6,G680) -> 0 | BR680: =COUNTIF(pick!$C$6:$I$6,H680) -> 0 | BS680: =COUNTIF(pick!$C$6:$I$6,I680) -> 0 | BT680: =COUNTIF(pick!$C$6:$I$6,J680) -> 0 | BU680: =COUNTIF(pick!$C$6:$I$6,K680) -> 0 | BV680: =SUM(BM680:BS680) -> 0 | BW680: =SUM(BT680:BU680) -> 0 | BX680: =SUM(BM680:BU680) -> 0
A681: 第679回 | M681: =COUNTIF(pick!$C$2:$I$2,C681) -> 0 | N681: =COUNTIF(pick!$C$2:$I$2,D681) -> 0 | O681: =COUNTIF(pick!$C$2:$I$2,E681) -> 0 | P681: =COUNTIF(pick!$C$2:$I$2,F681) -> 0 | Q681: =COUNTIF(pick!$C$2:$I$2,G681) -> 0 | R681: =COUNTIF(pick!$C$2:$I$2,H681) -> 0 | S681: =COUNTIF(pick!$C$2:$I$2,I681) -> 0 | T681: =COUNTIF(pick!$C$2:$I$2,J681) -> 0 | U681: =COUNTIF(pick!$C$2:$I$2,K681) -> 0 | V681: =SUM(M681:S681) -> 0 | W681: =SUM(T681:U681) -> 0 | X681: =SUM(M681:U681) -> 0 | Z681: =COUNTIF(pick!$C$3:$I$3,C681) -> 0 | AA681: =COUNTIF(pick!$C$3:$I$3,D681) -> 0 | AB681: =COUNTIF(pick!$C$3:$I$3,E681) -> 0 | AC681: =COUNTIF(pick!$C$3:$I$3,F681) -> 0 | AD681: =COUNTIF(pick!$C$3:$I$3,G681) -> 0 | AE681: =COUNTIF(pick!$C$3:$I$3,H681) -> 0 | AF681: =COUNTIF(pick!$C$3:$I$3,I681) -> 0 | AG681: =COUNTIF(pick!$C$3:$I$3,J681) -> 0 | AH681: =COUNTIF(pick!$C$3:$I$3,K681) -> 0 | AI681: =SUM(Z681:AF681) -> 0 | AJ681: =SUM(AG681:AH681) -> 0 | AK681: =SUM(Z681:AH681) -> 0 | AM681: =COUNTIF(pick!$C$4:$I$4,C681) -> 0 | AN681: =COUNTIF(pick!$C$4:$I$4,D681) -> 0 | AO681: =COUNTIF(pick!$C$4:$I$4,E681) -> 0 | AP681: =COUNTIF(pick!$C$4:$I$4,F681) -> 0 | AQ681: =COUNTIF(pick!$C$4:$I$4,G681) -> 0 | AR681: =COUNTIF(pick!$C$4:$I$4,H681) -> 0 | AS681: =COUNTIF(pick!$C$4:$I$4,I681) -> 0 | AT681: =COUNTIF(pick!$C$4:$I$4,J681) -> 0 | AU681: =COUNTIF(pick!$C$4:$I$4,K681) -> 0 | AV681: =SUM(AM681:AS681) -> 0 | AW681: =SUM(AT681:AU681) -> 0 | AX681: =SUM(AM681:AU681) -> 0 | AZ681: =COUNTIF(pick!$C$5:$I$5,C681) -> 0 | BA681: =COUNTIF(pick!$C$5:$I$5,D681) -> 0 | BB681: =COUNTIF(pick!$C$5:$I$5,E681) -> 0 | BC681: =COUNTIF(pick!$C$5:$I$5,F681) -> 0 | BD681: =COUNTIF(pick!$C$5:$I$5,G681) -> 0 | BE681: =COUNTIF(pick!$C$5:$I$5,H681) -> 0 | BF681: =COUNTIF(pick!$C$5:$I$5,I681) -> 0 | BG681: =COUNTIF(pick!$C$5:$I$5,J681) -> 0 | BH681: =COUNTIF(pick!$C$5:$I$5,K681) -> 0 | BI681: =SUM(AZ681:BF681) -> 0 | BJ681: =SUM(BG681:BH681) -> 0 | BK681: =SUM(AZ681:BH681) -> 0 | BM681: =COUNTIF(pick!$C$6:$I$6,C681) -> 0 | BN681: =COUNTIF(pick!$C$6:$I$6,D681) -> 0 | BO681: =COUNTIF(pick!$C$6:$I$6,E681) -> 0 | BP681: =COUNTIF(pick!$C$6:$I$6,F681) -> 0 | BQ681: =COUNTIF(pick!$C$6:$I$6,G681) -> 0 | BR681: =COUNTIF(pick!$C$6:$I$6,H681) -> 0 | BS681: =COUNTIF(pick!$C$6:$I$6,I681) -> 0 | BT681: =COUNTIF(pick!$C$6:$I$6,J681) -> 0 | BU681: =COUNTIF(pick!$C$6:$I$6,K681) -> 0 | BV681: =SUM(BM681:BS681) -> 0 | BW681: =SUM(BT681:BU681) -> 0 | BX681: =SUM(BM681:BU681) -> 0
A682: 第680回 | M682: =COUNTIF(pick!$C$2:$I$2,C682) -> 0 | N682: =COUNTIF(pick!$C$2:$I$2,D682) -> 0 | O682: =COUNTIF(pick!$C$2:$I$2,E682) -> 0 | P682: =COUNTIF(pick!$C$2:$I$2,F682) -> 0 | Q682: =COUNTIF(pick!$C$2:$I$2,G682) -> 0 | R682: =COUNTIF(pick!$C$2:$I$2,H682) -> 0 | S682: =COUNTIF(pick!$C$2:$I$2,I682) -> 0 | T682: =COUNTIF(pick!$C$2:$I$2,J682) -> 0 | U682: =COUNTIF(pick!$C$2:$I$2,K682) -> 0 | V682: =SUM(M682:S682) -> 0 | W682: =SUM(T682:U682) -> 0 | X682: =SUM(M682:U682) -> 0 | Z682: =COUNTIF(pick!$C$3:$I$3,C682) -> 0 | AA682: =COUNTIF(pick!$C$3:$I$3,D682) -> 0 | AB682: =COUNTIF(pick!$C$3:$I$3,E682) -> 0 | AC682: =COUNTIF(pick!$C$3:$I$3,F682) -> 0 | AD682: =COUNTIF(pick!$C$3:$I$3,G682) -> 0 | AE682: =COUNTIF(pick!$C$3:$I$3,H682) -> 0 | AF682: =COUNTIF(pick!$C$3:$I$3,I682) -> 0 | AG682: =COUNTIF(pick!$C$3:$I$3,J682) -> 0 | AH682: =COUNTIF(pick!$C$3:$I$3,K682) -> 0 | AI682: =SUM(Z682:AF682) -> 0 | AJ682: =SUM(AG682:AH682) -> 0 | AK682: =SUM(Z682:AH682) -> 0 | AM682: =COUNTIF(pick!$C$4:$I$4,C682) -> 0 | AN682: =COUNTIF(pick!$C$4:$I$4,D682) -> 0 | AO682: =COUNTIF(pick!$C$4:$I$4,E682) -> 0 | AP682: =COUNTIF(pick!$C$4:$I$4,F682) -> 0 | AQ682: =COUNTIF(pick!$C$4:$I$4,G682) -> 0 | AR682: =COUNTIF(pick!$C$4:$I$4,H682) -> 0 | AS682: =COUNTIF(pick!$C$4:$I$4,I682) -> 0 | AT682: =COUNTIF(pick!$C$4:$I$4,J682) -> 0 | AU682: =COUNTIF(pick!$C$4:$I$4,K682) -> 0 | AV682: =SUM(AM682:AS682) -> 0 | AW682: =SUM(AT682:AU682) -> 0 | AX682: =SUM(AM682:AU682) -> 0 | AZ682: =COUNTIF(pick!$C$5:$I$5,C682) -> 0 | BA682: =COUNTIF(pick!$C$5:$I$5,D682) -> 0 | BB682: =COUNTIF(pick!$C$5:$I$5,E682) -> 0 | BC682: =COUNTIF(pick!$C$5:$I$5,F682) -> 0 | BD682: =COUNTIF(pick!$C$5:$I$5,G682) -> 0 | BE682: =COUNTIF(pick!$C$5:$I$5,H682) -> 0 | BF682: =COUNTIF(pick!$C$5:$I$5,I682) -> 0 | BG682: =COUNTIF(pick!$C$5:$I$5,J682) -> 0 | BH682: =COUNTIF(pick!$C$5:$I$5,K682) -> 0 | BI682: =SUM(AZ682:BF682) -> 0 | BJ682: =SUM(BG682:BH682) -> 0 | BK682: =SUM(AZ682:BH682) -> 0 | BM682: =COUNTIF(pick!$C$6:$I$6,C682) -> 0 | BN682: =COUNTIF(pick!$C$6:$I$6,D682) -> 0 | BO682: =COUNTIF(pick!$C$6:$I$6,E682) -> 0 | BP682: =COUNTIF(pick!$C$6:$I$6,F682) -> 0 | BQ682: =COUNTIF(pick!$C$6:$I$6,G682) -> 0 | BR682: =COUNTIF(pick!$C$6:$I$6,H682) -> 0 | BS682: =COUNTIF(pick!$C$6:$I$6,I682) -> 0 | BT682: =COUNTIF(pick!$C$6:$I$6,J682) -> 0 | BU682: =COUNTIF(pick!$C$6:$I$6,K682) -> 0 | BV682: =SUM(BM682:BS682) -> 0 | BW682: =SUM(BT682:BU682) -> 0 | BX682: =SUM(BM682:BU682) -> 0
A683: 第681回 | M683: =COUNTIF(pick!$C$2:$I$2,C683) -> 0 | N683: =COUNTIF(pick!$C$2:$I$2,D683) -> 0 | O683: =COUNTIF(pick!$C$2:$I$2,E683) -> 0 | P683: =COUNTIF(pick!$C$2:$I$2,F683) -> 0 | Q683: =COUNTIF(pick!$C$2:$I$2,G683) -> 0 | R683: =COUNTIF(pick!$C$2:$I$2,H683) -> 0 | S683: =COUNTIF(pick!$C$2:$I$2,I683) -> 0 | T683: =COUNTIF(pick!$C$2:$I$2,J683) -> 0 | U683: =COUNTIF(pick!$C$2:$I$2,K683) -> 0 | V683: =SUM(M683:S683) -> 0 | W683: =SUM(T683:U683) -> 0 | X683: =SUM(M683:U683) -> 0 | Z683: =COUNTIF(pick!$C$3:$I$3,C683) -> 0 | AA683: =COUNTIF(pick!$C$3:$I$3,D683) -> 0 | AB683: =COUNTIF(pick!$C$3:$I$3,E683) -> 0 | AC683: =COUNTIF(pick!$C$3:$I$3,F683) -> 0 | AD683: =COUNTIF(pick!$C$3:$I$3,G683) -> 0 | AE683: =COUNTIF(pick!$C$3:$I$3,H683) -> 0 | AF683: =COUNTIF(pick!$C$3:$I$3,I683) -> 0 | AG683: =COUNTIF(pick!$C$3:$I$3,J683) -> 0 | AH683: =COUNTIF(pick!$C$3:$I$3,K683) -> 0 | AI683: =SUM(Z683:AF683) -> 0 | AJ683: =SUM(AG683:AH683) -> 0 | AK683: =SUM(Z683:AH683) -> 0 | AM683: =COUNTIF(pick!$C$4:$I$4,C683) -> 0 | AN683: =COUNTIF(pick!$C$4:$I$4,D683) -> 0 | AO683: =COUNTIF(pick!$C$4:$I$4,E683) -> 0 | AP683: =COUNTIF(pick!$C$4:$I$4,F683) -> 0 | AQ683: =COUNTIF(pick!$C$4:$I$4,G683) -> 0 | AR683: =COUNTIF(pick!$C$4:$I$4,H683) -> 0 | AS683: =COUNTIF(pick!$C$4:$I$4,I683) -> 0 | AT683: =COUNTIF(pick!$C$4:$I$4,J683) -> 0 | AU683: =COUNTIF(pick!$C$4:$I$4,K683) -> 0 | AV683: =SUM(AM683:AS683) -> 0 | AW683: =SUM(AT683:AU683) -> 0 | AX683: =SUM(AM683:AU683) -> 0 | AZ683: =COUNTIF(pick!$C$5:$I$5,C683) -> 0 | BA683: =COUNTIF(pick!$C$5:$I$5,D683) -> 0 | BB683: =COUNTIF(pick!$C$5:$I$5,E683) -> 0 | BC683: =COUNTIF(pick!$C$5:$I$5,F683) -> 0 | BD683: =COUNTIF(pick!$C$5:$I$5,G683) -> 0 | BE683: =COUNTIF(pick!$C$5:$I$5,H683) -> 0 | BF683: =COUNTIF(pick!$C$5:$I$5,I683) -> 0 | BG683: =COUNTIF(pick!$C$5:$I$5,J683) -> 0 | BH683: =COUNTIF(pick!$C$5:$I$5,K683) -> 0 | BI683: =SUM(AZ683:BF683) -> 0 | BJ683: =SUM(BG683:BH683) -> 0 | BK683: =SUM(AZ683:BH683) -> 0 | BM683: =COUNTIF(pick!$C$6:$I$6,C683) -> 0 | BN683: =COUNTIF(pick!$C$6:$I$6,D683) -> 0 | BO683: =COUNTIF(pick!$C$6:$I$6,E683) -> 0 | BP683: =COUNTIF(pick!$C$6:$I$6,F683) -> 0 | BQ683: =COUNTIF(pick!$C$6:$I$6,G683) -> 0 | BR683: =COUNTIF(pick!$C$6:$I$6,H683) -> 0 | BS683: =COUNTIF(pick!$C$6:$I$6,I683) -> 0 | BT683: =COUNTIF(pick!$C$6:$I$6,J683) -> 0 | BU683: =COUNTIF(pick!$C$6:$I$6,K683) -> 0 | BV683: =SUM(BM683:BS683) -> 0 | BW683: =SUM(BT683:BU683) -> 0 | BX683: =SUM(BM683:BU683) -> 0
A684: 第682回 | M684: =COUNTIF(pick!$C$2:$I$2,C684) -> 0 | N684: =COUNTIF(pick!$C$2:$I$2,D684) -> 0 | O684: =COUNTIF(pick!$C$2:$I$2,E684) -> 0 | P684: =COUNTIF(pick!$C$2:$I$2,F684) -> 0 | Q684: =COUNTIF(pick!$C$2:$I$2,G684) -> 0 | R684: =COUNTIF(pick!$C$2:$I$2,H684) -> 0 | S684: =COUNTIF(pick!$C$2:$I$2,I684) -> 0 | T684: =COUNTIF(pick!$C$2:$I$2,J684) -> 0 | U684: =COUNTIF(pick!$C$2:$I$2,K684) -> 0 | V684: =SUM(M684:S684) -> 0 | W684: =SUM(T684:U684) -> 0 | X684: =SUM(M684:U684) -> 0 | Z684: =COUNTIF(pick!$C$3:$I$3,C684) -> 0 | AA684: =COUNTIF(pick!$C$3:$I$3,D684) -> 0 | AB684: =COUNTIF(pick!$C$3:$I$3,E684) -> 0 | AC684: =COUNTIF(pick!$C$3:$I$3,F684) -> 0 | AD684: =COUNTIF(pick!$C$3:$I$3,G684) -> 0 | AE684: =COUNTIF(pick!$C$3:$I$3,H684) -> 0 | AF684: =COUNTIF(pick!$C$3:$I$3,I684) -> 0 | AG684: =COUNTIF(pick!$C$3:$I$3,J684) -> 0 | AH684: =COUNTIF(pick!$C$3:$I$3,K684) -> 0 | AI684: =SUM(Z684:AF684) -> 0 | AJ684: =SUM(AG684:AH684) -> 0 | AK684: =SUM(Z684:AH684) -> 0 | AM684: =COUNTIF(pick!$C$4:$I$4,C684) -> 0 | AN684: =COUNTIF(pick!$C$4:$I$4,D684) -> 0 | AO684: =COUNTIF(pick!$C$4:$I$4,E684) -> 0 | AP684: =COUNTIF(pick!$C$4:$I$4,F684) -> 0 | AQ684: =COUNTIF(pick!$C$4:$I$4,G684) -> 0 | AR684: =COUNTIF(pick!$C$4:$I$4,H684) -> 0 | AS684: =COUNTIF(pick!$C$4:$I$4,I684) -> 0 | AT684: =COUNTIF(pick!$C$4:$I$4,J684) -> 0 | AU684: =COUNTIF(pick!$C$4:$I$4,K684) -> 0 | AV684: =SUM(AM684:AS684) -> 0 | AW684: =SUM(AT684:AU684) -> 0 | AX684: =SUM(AM684:AU684) -> 0 | AZ684: =COUNTIF(pick!$C$5:$I$5,C684) -> 0 | BA684: =COUNTIF(pick!$C$5:$I$5,D684) -> 0 | BB684: =COUNTIF(pick!$C$5:$I$5,E684) -> 0 | BC684: =COUNTIF(pick!$C$5:$I$5,F684) -> 0 | BD684: =COUNTIF(pick!$C$5:$I$5,G684) -> 0 | BE684: =COUNTIF(pick!$C$5:$I$5,H684) -> 0 | BF684: =COUNTIF(pick!$C$5:$I$5,I684) -> 0 | BG684: =COUNTIF(pick!$C$5:$I$5,J684) -> 0 | BH684: =COUNTIF(pick!$C$5:$I$5,K684) -> 0 | BI684: =SUM(AZ684:BF684) -> 0 | BJ684: =SUM(BG684:BH684) -> 0 | BK684: =SUM(AZ684:BH684) -> 0 | BM684: =COUNTIF(pick!$C$6:$I$6,C684) -> 0 | BN684: =COUNTIF(pick!$C$6:$I$6,D684) -> 0 | BO684: =COUNTIF(pick!$C$6:$I$6,E684) -> 0 | BP684: =COUNTIF(pick!$C$6:$I$6,F684) -> 0 | BQ684: =COUNTIF(pick!$C$6:$I$6,G684) -> 0 | BR684: =COUNTIF(pick!$C$6:$I$6,H684) -> 0 | BS684: =COUNTIF(pick!$C$6:$I$6,I684) -> 0 | BT684: =COUNTIF(pick!$C$6:$I$6,J684) -> 0 | BU684: =COUNTIF(pick!$C$6:$I$6,K684) -> 0 | BV684: =SUM(BM684:BS684) -> 0 | BW684: =SUM(BT684:BU684) -> 0 | BX684: =SUM(BM684:BU684) -> 0
A685: 第683回 | M685: =COUNTIF(pick!$C$2:$I$2,C685) -> 0 | N685: =COUNTIF(pick!$C$2:$I$2,D685) -> 0 | O685: =COUNTIF(pick!$C$2:$I$2,E685) -> 0 | P685: =COUNTIF(pick!$C$2:$I$2,F685) -> 0 | Q685: =COUNTIF(pick!$C$2:$I$2,G685) -> 0 | R685: =COUNTIF(pick!$C$2:$I$2,H685) -> 0 | S685: =COUNTIF(pick!$C$2:$I$2,I685) -> 0 | T685: =COUNTIF(pick!$C$2:$I$2,J685) -> 0 | U685: =COUNTIF(pick!$C$2:$I$2,K685) -> 0 | V685: =SUM(M685:S685) -> 0 | W685: =SUM(T685:U685) -> 0 | X685: =SUM(M685:U685) -> 0 | Z685: =COUNTIF(pick!$C$3:$I$3,C685) -> 0 | AA685: =COUNTIF(pick!$C$3:$I$3,D685) -> 0 | AB685: =COUNTIF(pick!$C$3:$I$3,E685) -> 0 | AC685: =COUNTIF(pick!$C$3:$I$3,F685) -> 0 | AD685: =COUNTIF(pick!$C$3:$I$3,G685) -> 0 | AE685: =COUNTIF(pick!$C$3:$I$3,H685) -> 0 | AF685: =COUNTIF(pick!$C$3:$I$3,I685) -> 0 | AG685: =COUNTIF(pick!$C$3:$I$3,J685) -> 0 | AH685: =COUNTIF(pick!$C$3:$I$3,K685) -> 0 | AI685: =SUM(Z685:AF685) -> 0 | AJ685: =SUM(AG685:AH685) -> 0 | AK685: =SUM(Z685:AH685) -> 0 | AM685: =COUNTIF(pick!$C$4:$I$4,C685) -> 0 | AN685: =COUNTIF(pick!$C$4:$I$4,D685) -> 0 | AO685: =COUNTIF(pick!$C$4:$I$4,E685) -> 0 | AP685: =COUNTIF(pick!$C$4:$I$4,F685) -> 0 | AQ685: =COUNTIF(pick!$C$4:$I$4,G685) -> 0 | AR685: =COUNTIF(pick!$C$4:$I$4,H685) -> 0 | AS685: =COUNTIF(pick!$C$4:$I$4,I685) -> 0 | AT685: =COUNTIF(pick!$C$4:$I$4,J685) -> 0 | AU685: =COUNTIF(pick!$C$4:$I$4,K685) -> 0 | AV685: =SUM(AM685:AS685) -> 0 | AW685: =SUM(AT685:AU685) -> 0 | AX685: =SUM(AM685:AU685) -> 0 | AZ685: =COUNTIF(pick!$C$5:$I$5,C685) -> 0 | BA685: =COUNTIF(pick!$C$5:$I$5,D685) -> 0 | BB685: =COUNTIF(pick!$C$5:$I$5,E685) -> 0 | BC685: =COUNTIF(pick!$C$5:$I$5,F685) -> 0 | BD685: =COUNTIF(pick!$C$5:$I$5,G685) -> 0 | BE685: =COUNTIF(pick!$C$5:$I$5,H685) -> 0 | BF685: =COUNTIF(pick!$C$5:$I$5,I685) -> 0 | BG685: =COUNTIF(pick!$C$5:$I$5,J685) -> 0 | BH685: =COUNTIF(pick!$C$5:$I$5,K685) -> 0 | BI685: =SUM(AZ685:BF685) -> 0 | BJ685: =SUM(BG685:BH685) -> 0 | BK685: =SUM(AZ685:BH685) -> 0 | BM685: =COUNTIF(pick!$C$6:$I$6,C685) -> 0 | BN685: =COUNTIF(pick!$C$6:$I$6,D685) -> 0 | BO685: =COUNTIF(pick!$C$6:$I$6,E685) -> 0 | BP685: =COUNTIF(pick!$C$6:$I$6,F685) -> 0 | BQ685: =COUNTIF(pick!$C$6:$I$6,G685) -> 0 | BR685: =COUNTIF(pick!$C$6:$I$6,H685) -> 0 | BS685: =COUNTIF(pick!$C$6:$I$6,I685) -> 0 | BT685: =COUNTIF(pick!$C$6:$I$6,J685) -> 0 | BU685: =COUNTIF(pick!$C$6:$I$6,K685) -> 0 | BV685: =SUM(BM685:BS685) -> 0 | BW685: =SUM(BT685:BU685) -> 0 | BX685: =SUM(BM685:BU685) -> 0
A686: 第684回 | M686: =COUNTIF(pick!$C$2:$I$2,C686) -> 0 | N686: =COUNTIF(pick!$C$2:$I$2,D686) -> 0 | O686: =COUNTIF(pick!$C$2:$I$2,E686) -> 0 | P686: =COUNTIF(pick!$C$2:$I$2,F686) -> 0 | Q686: =COUNTIF(pick!$C$2:$I$2,G686) -> 0 | R686: =COUNTIF(pick!$C$2:$I$2,H686) -> 0 | S686: =COUNTIF(pick!$C$2:$I$2,I686) -> 0 | T686: =COUNTIF(pick!$C$2:$I$2,J686) -> 0 | U686: =COUNTIF(pick!$C$2:$I$2,K686) -> 0 | V686: =SUM(M686:S686) -> 0 | W686: =SUM(T686:U686) -> 0 | X686: =SUM(M686:U686) -> 0 | Z686: =COUNTIF(pick!$C$3:$I$3,C686) -> 0 | AA686: =COUNTIF(pick!$C$3:$I$3,D686) -> 0 | AB686: =COUNTIF(pick!$C$3:$I$3,E686) -> 0 | AC686: =COUNTIF(pick!$C$3:$I$3,F686) -> 0 | AD686: =COUNTIF(pick!$C$3:$I$3,G686) -> 0 | AE686: =COUNTIF(pick!$C$3:$I$3,H686) -> 0 | AF686: =COUNTIF(pick!$C$3:$I$3,I686) -> 0 | AG686: =COUNTIF(pick!$C$3:$I$3,J686) -> 0 | AH686: =COUNTIF(pick!$C$3:$I$3,K686) -> 0 | AI686: =SUM(Z686:AF686) -> 0 | AJ686: =SUM(AG686:AH686) -> 0 | AK686: =SUM(Z686:AH686) -> 0 | AM686: =COUNTIF(pick!$C$4:$I$4,C686) -> 0 | AN686: =COUNTIF(pick!$C$4:$I$4,D686) -> 0 | AO686: =COUNTIF(pick!$C$4:$I$4,E686) -> 0 | AP686: =COUNTIF(pick!$C$4:$I$4,F686) -> 0 | AQ686: =COUNTIF(pick!$C$4:$I$4,G686) -> 0 | AR686: =COUNTIF(pick!$C$4:$I$4,H686) -> 0 | AS686: =COUNTIF(pick!$C$4:$I$4,I686) -> 0 | AT686: =COUNTIF(pick!$C$4:$I$4,J686) -> 0 | AU686: =COUNTIF(pick!$C$4:$I$4,K686) -> 0 | AV686: =SUM(AM686:AS686) -> 0 | AW686: =SUM(AT686:AU686) -> 0 | AX686: =SUM(AM686:AU686) -> 0 | AZ686: =COUNTIF(pick!$C$5:$I$5,C686) -> 0 | BA686: =COUNTIF(pick!$C$5:$I$5,D686) -> 0 | BB686: =COUNTIF(pick!$C$5:$I$5,E686) -> 0 | BC686: =COUNTIF(pick!$C$5:$I$5,F686) -> 0 | BD686: =COUNTIF(pick!$C$5:$I$5,G686) -> 0 | BE686: =COUNTIF(pick!$C$5:$I$5,H686) -> 0 | BF686: =COUNTIF(pick!$C$5:$I$5,I686) -> 0 | BG686: =COUNTIF(pick!$C$5:$I$5,J686) -> 0 | BH686: =COUNTIF(pick!$C$5:$I$5,K686) -> 0 | BI686: =SUM(AZ686:BF686) -> 0 | BJ686: =SUM(BG686:BH686) -> 0 | BK686: =SUM(AZ686:BH686) -> 0 | BM686: =COUNTIF(pick!$C$6:$I$6,C686) -> 0 | BN686: =COUNTIF(pick!$C$6:$I$6,D686) -> 0 | BO686: =COUNTIF(pick!$C$6:$I$6,E686) -> 0 | BP686: =COUNTIF(pick!$C$6:$I$6,F686) -> 0 | BQ686: =COUNTIF(pick!$C$6:$I$6,G686) -> 0 | BR686: =COUNTIF(pick!$C$6:$I$6,H686) -> 0 | BS686: =COUNTIF(pick!$C$6:$I$6,I686) -> 0 | BT686: =COUNTIF(pick!$C$6:$I$6,J686) -> 0 | BU686: =COUNTIF(pick!$C$6:$I$6,K686) -> 0 | BV686: =SUM(BM686:BS686) -> 0 | BW686: =SUM(BT686:BU686) -> 0 | BX686: =SUM(BM686:BU686) -> 0
A687: 第685回 | M687: =COUNTIF(pick!$C$2:$I$2,C687) -> 0 | N687: =COUNTIF(pick!$C$2:$I$2,D687) -> 0 | O687: =COUNTIF(pick!$C$2:$I$2,E687) -> 0 | P687: =COUNTIF(pick!$C$2:$I$2,F687) -> 0 | Q687: =COUNTIF(pick!$C$2:$I$2,G687) -> 0 | R687: =COUNTIF(pick!$C$2:$I$2,H687) -> 0 | S687: =COUNTIF(pick!$C$2:$I$2,I687) -> 0 | T687: =COUNTIF(pick!$C$2:$I$2,J687) -> 0 | U687: =COUNTIF(pick!$C$2:$I$2,K687) -> 0 | V687: =SUM(M687:S687) -> 0 | W687: =SUM(T687:U687) -> 0 | X687: =SUM(M687:U687) -> 0 | Z687: =COUNTIF(pick!$C$3:$I$3,C687) -> 0 | AA687: =COUNTIF(pick!$C$3:$I$3,D687) -> 0 | AB687: =COUNTIF(pick!$C$3:$I$3,E687) -> 0 | AC687: =COUNTIF(pick!$C$3:$I$3,F687) -> 0 | AD687: =COUNTIF(pick!$C$3:$I$3,G687) -> 0 | AE687: =COUNTIF(pick!$C$3:$I$3,H687) -> 0 | AF687: =COUNTIF(pick!$C$3:$I$3,I687) -> 0 | AG687: =COUNTIF(pick!$C$3:$I$3,J687) -> 0 | AH687: =COUNTIF(pick!$C$3:$I$3,K687) -> 0 | AI687: =SUM(Z687:AF687) -> 0 | AJ687: =SUM(AG687:AH687) -> 0 | AK687: =SUM(Z687:AH687) -> 0 | AM687: =COUNTIF(pick!$C$4:$I$4,C687) -> 0 | AN687: =COUNTIF(pick!$C$4:$I$4,D687) -> 0 | AO687: =COUNTIF(pick!$C$4:$I$4,E687) -> 0 | AP687: =COUNTIF(pick!$C$4:$I$4,F687) -> 0 | AQ687: =COUNTIF(pick!$C$4:$I$4,G687) -> 0 | AR687: =COUNTIF(pick!$C$4:$I$4,H687) -> 0 | AS687: =COUNTIF(pick!$C$4:$I$4,I687) -> 0 | AT687: =COUNTIF(pick!$C$4:$I$4,J687) -> 0 | AU687: =COUNTIF(pick!$C$4:$I$4,K687) -> 0 | AV687: =SUM(AM687:AS687) -> 0 | AW687: =SUM(AT687:AU687) -> 0 | AX687: =SUM(AM687:AU687) -> 0 | AZ687: =COUNTIF(pick!$C$5:$I$5,C687) -> 0 | BA687: =COUNTIF(pick!$C$5:$I$5,D687) -> 0 | BB687: =COUNTIF(pick!$C$5:$I$5,E687) -> 0 | BC687: =COUNTIF(pick!$C$5:$I$5,F687) -> 0 | BD687: =COUNTIF(pick!$C$5:$I$5,G687) -> 0 | BE687: =COUNTIF(pick!$C$5:$I$5,H687) -> 0 | BF687: =COUNTIF(pick!$C$5:$I$5,I687) -> 0 | BG687: =COUNTIF(pick!$C$5:$I$5,J687) -> 0 | BH687: =COUNTIF(pick!$C$5:$I$5,K687) -> 0 | BI687: =SUM(AZ687:BF687) -> 0 | BJ687: =SUM(BG687:BH687) -> 0 | BK687: =SUM(AZ687:BH687) -> 0 | BM687: =COUNTIF(pick!$C$6:$I$6,C687) -> 0 | BN687: =COUNTIF(pick!$C$6:$I$6,D687) -> 0 | BO687: =COUNTIF(pick!$C$6:$I$6,E687) -> 0 | BP687: =COUNTIF(pick!$C$6:$I$6,F687) -> 0 | BQ687: =COUNTIF(pick!$C$6:$I$6,G687) -> 0 | BR687: =COUNTIF(pick!$C$6:$I$6,H687) -> 0 | BS687: =COUNTIF(pick!$C$6:$I$6,I687) -> 0 | BT687: =COUNTIF(pick!$C$6:$I$6,J687) -> 0 | BU687: =COUNTIF(pick!$C$6:$I$6,K687) -> 0 | BV687: =SUM(BM687:BS687) -> 0 | BW687: =SUM(BT687:BU687) -> 0 | BX687: =SUM(BM687:BU687) -> 0
A688: 第686回 | M688: =COUNTIF(pick!$C$2:$I$2,C688) -> 0 | N688: =COUNTIF(pick!$C$2:$I$2,D688) -> 0 | O688: =COUNTIF(pick!$C$2:$I$2,E688) -> 0 | P688: =COUNTIF(pick!$C$2:$I$2,F688) -> 0 | Q688: =COUNTIF(pick!$C$2:$I$2,G688) -> 0 | R688: =COUNTIF(pick!$C$2:$I$2,H688) -> 0 | S688: =COUNTIF(pick!$C$2:$I$2,I688) -> 0 | T688: =COUNTIF(pick!$C$2:$I$2,J688) -> 0 | U688: =COUNTIF(pick!$C$2:$I$2,K688) -> 0 | V688: =SUM(M688:S688) -> 0 | W688: =SUM(T688:U688) -> 0 | X688: =SUM(M688:U688) -> 0 | Z688: =COUNTIF(pick!$C$3:$I$3,C688) -> 0 | AA688: =COUNTIF(pick!$C$3:$I$3,D688) -> 0 | AB688: =COUNTIF(pick!$C$3:$I$3,E688) -> 0 | AC688: =COUNTIF(pick!$C$3:$I$3,F688) -> 0 | AD688: =COUNTIF(pick!$C$3:$I$3,G688) -> 0 | AE688: =COUNTIF(pick!$C$3:$I$3,H688) -> 0 | AF688: =COUNTIF(pick!$C$3:$I$3,I688) -> 0 | AG688: =COUNTIF(pick!$C$3:$I$3,J688) -> 0 | AH688: =COUNTIF(pick!$C$3:$I$3,K688) -> 0 | AI688: =SUM(Z688:AF688) -> 0 | AJ688: =SUM(AG688:AH688) -> 0 | AK688: =SUM(Z688:AH688) -> 0 | AM688: =COUNTIF(pick!$C$4:$I$4,C688) -> 0 | AN688: =COUNTIF(pick!$C$4:$I$4,D688) -> 0 | AO688: =COUNTIF(pick!$C$4:$I$4,E688) -> 0 | AP688: =COUNTIF(pick!$C$4:$I$4,F688) -> 0 | AQ688: =COUNTIF(pick!$C$4:$I$4,G688) -> 0 | AR688: =COUNTIF(pick!$C$4:$I$4,H688) -> 0 | AS688: =COUNTIF(pick!$C$4:$I$4,I688) -> 0 | AT688: =COUNTIF(pick!$C$4:$I$4,J688) -> 0 | AU688: =COUNTIF(pick!$C$4:$I$4,K688) -> 0 | AV688: =SUM(AM688:AS688) -> 0 | AW688: =SUM(AT688:AU688) -> 0 | AX688: =SUM(AM688:AU688) -> 0 | AZ688: =COUNTIF(pick!$C$5:$I$5,C688) -> 0 | BA688: =COUNTIF(pick!$C$5:$I$5,D688) -> 0 | BB688: =COUNTIF(pick!$C$5:$I$5,E688) -> 0 | BC688: =COUNTIF(pick!$C$5:$I$5,F688) -> 0 | BD688: =COUNTIF(pick!$C$5:$I$5,G688) -> 0 | BE688: =COUNTIF(pick!$C$5:$I$5,H688) -> 0 | BF688: =COUNTIF(pick!$C$5:$I$5,I688) -> 0 | BG688: =COUNTIF(pick!$C$5:$I$5,J688) -> 0 | BH688: =COUNTIF(pick!$C$5:$I$5,K688) -> 0 | BI688: =SUM(AZ688:BF688) -> 0 | BJ688: =SUM(BG688:BH688) -> 0 | BK688: =SUM(AZ688:BH688) -> 0 | BM688: =COUNTIF(pick!$C$6:$I$6,C688) -> 0 | BN688: =COUNTIF(pick!$C$6:$I$6,D688) -> 0 | BO688: =COUNTIF(pick!$C$6:$I$6,E688) -> 0 | BP688: =COUNTIF(pick!$C$6:$I$6,F688) -> 0 | BQ688: =COUNTIF(pick!$C$6:$I$6,G688) -> 0 | BR688: =COUNTIF(pick!$C$6:$I$6,H688) -> 0 | BS688: =COUNTIF(pick!$C$6:$I$6,I688) -> 0 | BT688: =COUNTIF(pick!$C$6:$I$6,J688) -> 0 | BU688: =COUNTIF(pick!$C$6:$I$6,K688) -> 0 | BV688: =SUM(BM688:BS688) -> 0 | BW688: =SUM(BT688:BU688) -> 0 | BX688: =SUM(BM688:BU688) -> 0
A689: 第687回 | M689: =COUNTIF(pick!$C$2:$I$2,C689) -> 0 | N689: =COUNTIF(pick!$C$2:$I$2,D689) -> 0 | O689: =COUNTIF(pick!$C$2:$I$2,E689) -> 0 | P689: =COUNTIF(pick!$C$2:$I$2,F689) -> 0 | Q689: =COUNTIF(pick!$C$2:$I$2,G689) -> 0 | R689: =COUNTIF(pick!$C$2:$I$2,H689) -> 0 | S689: =COUNTIF(pick!$C$2:$I$2,I689) -> 0 | T689: =COUNTIF(pick!$C$2:$I$2,J689) -> 0 | U689: =COUNTIF(pick!$C$2:$I$2,K689) -> 0 | V689: =SUM(M689:S689) -> 0 | W689: =SUM(T689:U689) -> 0 | X689: =SUM(M689:U689) -> 0 | Z689: =COUNTIF(pick!$C$3:$I$3,C689) -> 0 | AA689: =COUNTIF(pick!$C$3:$I$3,D689) -> 0 | AB689: =COUNTIF(pick!$C$3:$I$3,E689) -> 0 | AC689: =COUNTIF(pick!$C$3:$I$3,F689) -> 0 | AD689: =COUNTIF(pick!$C$3:$I$3,G689) -> 0 | AE689: =COUNTIF(pick!$C$3:$I$3,H689) -> 0 | AF689: =COUNTIF(pick!$C$3:$I$3,I689) -> 0 | AG689: =COUNTIF(pick!$C$3:$I$3,J689) -> 0 | AH689: =COUNTIF(pick!$C$3:$I$3,K689) -> 0 | AI689: =SUM(Z689:AF689) -> 0 | AJ689: =SUM(AG689:AH689) -> 0 | AK689: =SUM(Z689:AH689) -> 0 | AM689: =COUNTIF(pick!$C$4:$I$4,C689) -> 0 | AN689: =COUNTIF(pick!$C$4:$I$4,D689) -> 0 | AO689: =COUNTIF(pick!$C$4:$I$4,E689) -> 0 | AP689: =COUNTIF(pick!$C$4:$I$4,F689) -> 0 | AQ689: =COUNTIF(pick!$C$4:$I$4,G689) -> 0 | AR689: =COUNTIF(pick!$C$4:$I$4,H689) -> 0 | AS689: =COUNTIF(pick!$C$4:$I$4,I689) -> 0 | AT689: =COUNTIF(pick!$C$4:$I$4,J689) -> 0 | AU689: =COUNTIF(pick!$C$4:$I$4,K689) -> 0 | AV689: =SUM(AM689:AS689) -> 0 | AW689: =SUM(AT689:AU689) -> 0 | AX689: =SUM(AM689:AU689) -> 0 | AZ689: =COUNTIF(pick!$C$5:$I$5,C689) -> 0 | BA689: =COUNTIF(pick!$C$5:$I$5,D689) -> 0 | BB689: =COUNTIF(pick!$C$5:$I$5,E689) -> 0 | BC689: =COUNTIF(pick!$C$5:$I$5,F689) -> 0 | BD689: =COUNTIF(pick!$C$5:$I$5,G689) -> 0 | BE689: =COUNTIF(pick!$C$5:$I$5,H689) -> 0 | BF689: =COUNTIF(pick!$C$5:$I$5,I689) -> 0 | BG689: =COUNTIF(pick!$C$5:$I$5,J689) -> 0 | BH689: =COUNTIF(pick!$C$5:$I$5,K689) -> 0 | BI689: =SUM(AZ689:BF689) -> 0 | BJ689: =SUM(BG689:BH689) -> 0 | BK689: =SUM(AZ689:BH689) -> 0 | BM689: =COUNTIF(pick!$C$6:$I$6,C689) -> 0 | BN689: =COUNTIF(pick!$C$6:$I$6,D689) -> 0 | BO689: =COUNTIF(pick!$C$6:$I$6,E689) -> 0 | BP689: =COUNTIF(pick!$C$6:$I$6,F689) -> 0 | BQ689: =COUNTIF(pick!$C$6:$I$6,G689) -> 0 | BR689: =COUNTIF(pick!$C$6:$I$6,H689) -> 0 | BS689: =COUNTIF(pick!$C$6:$I$6,I689) -> 0 | BT689: =COUNTIF(pick!$C$6:$I$6,J689) -> 0 | BU689: =COUNTIF(pick!$C$6:$I$6,K689) -> 0 | BV689: =SUM(BM689:BS689) -> 0 | BW689: =SUM(BT689:BU689) -> 0 | BX689: =SUM(BM689:BU689) -> 0
